<?xml version="1.0" ?>

<sdf version="1.6">
  <world name="SRC_finals">

    <physics type="ode">
      <real_time_update_rate>1000.0</real_time_update_rate>
      <max_step_size>0.001</max_step_size>
      <real_time_factor>1</real_time_factor>
      <ode>
        <solver>
          <type>quick</type>
          <iters>150</iters>
          <precon_iters>0</precon_iters>
          <sor>1.400000</sor>
          <use_dynamic_moi_rescaling>1</use_dynamic_moi_rescaling>
        </solver>
        <constraints>
          <cfm>0.000000</cfm>
          <erp>0.800000</erp>
          <contact_max_correcting_vel>2000.000000</contact_max_correcting_vel>
          <contact_surface_layer>0.01000</contact_surface_layer>
        </constraints>
      </ode>
    </physics>

    <!-- GUI -->
    <gui fullscreen='0'>
      <camera name='user_camera'>
        <pose>-4.1 -0.2 3.3 0 0.37 0</pose>
      </camera>
    </gui>

    <!-- Scene -->
    <scene>
      <background>0.968627451 0.690196078 0.384313725 1.0</background>
      <grid>0</grid>
      <origin_visual>0</origin_visual>
    </scene>

    <!-- A global light source -->
    <light type="directional" name="sun">
      <cast_shadows>true</cast_shadows>
      <pose>0 0 1000 0.553468941484524 -1.3534965334257645 0</pose>
      <diffuse>0.8 0.8 0.8 1</diffuse>
      <specular>0.2 0.2 0.2 1</specular>
      <attenuation>
        <range>1000</range>
        <constant>0.9</constant>
        <linear>0.01</linear>
        <quadratic>0.001</quadratic>
      </attenuation>
      <direction>-0.5 0.1 -0.9</direction>
    </light>

    <!-- Background -->
    <include>
      <uri>model://heightmap_mars</uri>
    </include>

    <!-- START WALKWAY -->

    <!-- Walkway -->
    <include>
      <name>walkway_1</name>
      <pose>
      0.09
      0
      -0.052151
      0
      0
      3.141592653589793
      </pose>
      <uri>model://walkway_finish_opposite</uri>
    </include>


    <!-- Bling -->
    <include>
      <name>bling_1</name>
      <pose>
      0.08999999999999976
      -1.924
      0
      0
      0
      3.141592653589793
      </pose>
      <uri>model://mars_crate</uri>
    </include>


    <!-- Bling -->
    <include>
      <name>bling_2</name>
      <pose>
      0.0900000000000003
      2.024
      0
      0
      0
      -2.4492935982947064e-16
      </pose>
      <uri>model://mars_rock_2</uri>
    </include>




    <!-- TASK 1 -->

    <!-- Task 1 start - Box plugin -->


    <plugin name="boxT1Start" filename="libBoxContainsPlugin.so">
      <entity>valkyrie</entity>
      <namespace>task1/start</namespace>
      <pose>
        2.114
        -2.784846821261081e-16
        2.5
        0
        0
        -1.5707963267948968
      </pose>
      <size>1.524 1 5.0</size>
    </plugin>

    <!-- Walkway -->
    <include>
      <name>walkway_2</name>
      <pose>
      2.914734
      0.5394700919999995
      -0.052151
      0
      0
      2.356194490192345
      </pose>
      <uri>model://walkway_metal_45</uri>
    </include>


    <!-- Satellite -->




<model name="satellite_dish">

  <pose>
    2.3866949400811333
    -2.8506735555415057
    0
    0
    0
    3.141592653589793
  </pose>

  <link name="base">
    <inertial>
      <pose>0 -0.6077 0.3193 0 0 0</pose>
      <inertia>
        <ixx>165.1022</ixx>
        <ixy>0</ixy>
        <ixz>0</ixz>
        <iyy>13.8377</iyy>
        <iyz>0</iyz>
        <izz>170.3359</izz>
      </inertia>
      <mass>400</mass>
    </inertial>
    <collision name="collision">
      <geometry>
        <mesh>
          <uri>model://satellite_dish/meshes/satellite_dish.obj</uri>
          <submesh>
            <name>Base</name>
          </submesh>
          <scale>0.001 0.001 0.001</scale>
        </mesh>
      </geometry>
    </collision>
    <visual name="visual">
      <geometry>
        <mesh>
          <uri>model://satellite_dish/meshes/satellite_dish.obj</uri>
          <submesh>
            <name>Base</name>
          </submesh>
          <scale>0.001 0.001 0.001</scale>
        </mesh>
      </geometry>
    </visual>
  </link>

  <link name="pivot">
    <pose>0 0 1.595 0 0 0</pose>
    <inertial>
      <inertia>
        <ixx>0.00073</ixx>
        <ixy>0</ixy>
        <ixz>0</ixz>
        <iyy>0.000598</iyy>
        <iyz>0</iyz>
        <izz>0.00057</izz>
      </inertia>
      <mass>0.82</mass>
    </inertial>
    <collision name="collision">
      <pose>0 0 -1.595 0 0 0</pose>
      <geometry>
        <mesh>
          <uri>model://satellite_dish/meshes/satellite_dish.obj</uri>
          <submesh>
            <name>Pivot</name>
          </submesh>
          <scale>0.001 0.001 0.001</scale>
        </mesh>
      </geometry>
    </collision>
    <visual name="visual">
      <pose>0 0 -1.595 0 0 0</pose>
      <geometry>
        <mesh>
          <uri>model://satellite_dish/meshes/satellite_dish.obj</uri>
          <submesh>
            <name>Pivot</name>
          </submesh>
          <scale>0.001 0.001 0.001</scale>
        </mesh>
      </geometry>
    </visual>
  </link>

  <link name="dish">
    <pose>0 0 1.595 0.43 0 0</pose>
    <inertial>
      <pose>0 0.2 0 0 0 0</pose>
      <inertia>
        <ixx>0.92468</ixx>
        <ixy>0</ixy>
        <ixz>0</ixz>
        <iyy>1.87729</iyy>
        <iyz>0</iyz>
        <izz>0.97826</izz>
      </inertia>
      <mass>17.0</mass>
    </inertial>
    <collision name="collision">
      <pose>0 -0.6519041 -1.451541 -0.43 0 0</pose>
      <geometry>
        <mesh>
          <uri>model://satellite_dish/meshes/satellite_dish.obj</uri>
          <submesh>
            <name>Dish</name>
          </submesh>
          <scale>0.001 0.001 0.001</scale>
        </mesh>
      </geometry>
    </collision>
    <visual name="visual">
      <pose>0 -0.6519041 -1.451541 -0.43 0 0</pose>
      <geometry>
        <mesh>
          <uri>model://satellite_dish/meshes/satellite_dish.obj</uri>
          <submesh>
            <name>Dish</name>
          </submesh>
          <scale>0.001 0.001 0.001</scale>
        </mesh>
      </geometry>
    </visual>
  </link>

  <link name="wheel_yaw">
    <pose>-0.2 -1.725 0.91 0.52 0 0</pose>
    <inertial>
      <inertia>
        <ixx>0.0123</ixx>
        <ixy>0</ixy>
        <ixz>0</ixz>
        <iyy>0.01295</iyy>
        <iyz>0</iyz>
        <izz>0.02500</izz>
      </inertia>
      <mass>2.0</mass>
    </inertial>
    <collision name="collision">
      <pose>0.2 1.060 -1.64 -0.52 0 0</pose>
      <geometry>
        <mesh>
          <uri>model://satellite_dish/meshes/satellite_dish.obj</uri>
          <submesh>
            <name>Wheel_01</name>
          </submesh>
          <scale>0.001 0.001 0.001</scale>
        </mesh>
      </geometry>
    </collision>
    <collision name="collision_sphere">
      <pose>0.002 -0.123 0.082 0 0 0</pose>
      <geometry>
        <sphere>
          <radius>0.029</radius>
        </sphere>
      </geometry>
    </collision>
    <collision name="collision_cylinder">
      <pose>0.002 -0.122 0.025 0 0 0</pose>
      <geometry>
        <cylinder>
          <length>0.06</length>
          <radius>0.0125</radius>
        </cylinder>
      </geometry>
    </collision>
    <visual name="visual">
      <pose>0.2 1.060 -1.64 -0.52 0 0</pose>
      <geometry>
        <mesh>
          <uri>model://satellite_dish/meshes/satellite_dish.obj</uri>
          <submesh>
            <name>Wheel_01</name>
          </submesh>
          <scale>0.001 0.001 0.001</scale>
        </mesh>
      </geometry>
    </visual>
  </link>

  <link name="wheel_pitch">
    <pose>0.2 -1.725 0.91 0.52 0 0</pose>
    <inertial>
      <inertia>
        <ixx>0.0123</ixx>
        <ixy>0</ixy>
        <ixz>0</ixz>
        <iyy>0.01295</iyy>
        <iyz>0</iyz>
        <izz>0.02500</izz>
      </inertia>
      <mass>2.0</mass>
    </inertial>
    <collision name="collision">
      <pose>-0.2 1.060 -1.64 -0.52 0 0</pose>
      <geometry>
        <mesh>
          <uri>model://satellite_dish/meshes/satellite_dish.obj</uri>
          <submesh>
            <name>Wheel_02</name>
          </submesh>
          <scale>0.001 0.001 0.001</scale>
        </mesh>
      </geometry>
    </collision>
    <collision name="collision_sphere">
      <pose>-0.002 -0.123 0.082 0 0 0</pose>
      <geometry>
        <sphere>
          <radius>0.029</radius>
        </sphere>
      </geometry>
    </collision>
    <collision name="collision_cylinder">
      <pose>-0.002 -0.122 0.025 0 0 0</pose>
      <geometry>
        <cylinder>
          <length>0.06</length>
          <radius>0.0125</radius>
        </cylinder>
      </geometry>
    </collision>
    <visual name="visual">
      <pose>-0.2 1.060 -1.64 -0.52 0 0</pose>
      <geometry>
        <mesh>
          <uri>model://satellite_dish/meshes/satellite_dish.obj</uri>
          <submesh>
            <name>Wheel_02</name>
          </submesh>
          <scale>0.001 0.001 0.001</scale>
        </mesh>
      </geometry>
    </visual>
  </link>

  <joint name="dish_yaw" type="revolute">
    <parent>base</parent>
    <child>pivot</child>
    <axis>
      <xyz>0 0 -1</xyz>
      <dynamics>
        <damping>1000</damping>
      </dynamics>
    </axis>
  </joint>

  <joint name="dish_pitch" type="revolute">
    <parent>pivot</parent>
    <child>dish</child>
    <axis>
      <xyz>1 0 0</xyz>
      <limit>
        <lower>-0.2</lower>
        <upper>1.57</upper>
      </limit>
      <dynamics>
        <damping>100</damping>
      </dynamics>
    </axis>
  </joint>

  <joint name="wheel_yaw" type="revolute">
    <parent>base</parent>
    <child>wheel_yaw</child>
    <axis>
      <xyz>0 0 -1</xyz>
      <dynamics>
        <friction>2.5638787550831914</friction>
      </dynamics>
    </axis>
  </joint>

  <joint name="wheel_pitch" type="revolute">
    <parent>base</parent>
    <child>wheel_pitch</child>
    <axis>
      <xyz>0 0 -1</xyz>
      <dynamics>
        <friction>2.613197485283815</friction>
      </dynamics>
    </axis>
  </joint>

  <joint name="satellite_world" type="fixed">
    <parent>world</parent>
    <child>base</child>
  </joint>

  <plugin name="satellite_plugin" filename="libSatellitePlugin.so">

    <yaw_ratio>0.1</yaw_ratio>
    <yaw_pid>1000 0 10</yaw_pid>
    <yaw_target>0.9175538255778255</yaw_target>

    <pitch_ratio>0.1</pitch_ratio>
    <pitch_pid>1000 100 10</pitch_pid>
    <pitch_target>0.0865098610058731</pitch_target>

    <!-- Tolerance in degrees -->
    <tolerance>5</tolerance>

    <!-- Target time to hold position in seconds -->
    <time>5</time>

    <topic>/task1/checkpoint2/satellite</topic>
    <frequency>100</frequency>

  </plugin>

</model>


    <!-- Checkpoint 1 - Box plugin -->


    <plugin name="boxT1CP1" filename="libBoxContainsPlugin.so">
      <entity>valkyrie</entity>
      <namespace>task1/checkpoint1</namespace>
      <pose>
        2.3866949400811337
        -0.4506735555415058
        2.5
        0
        0
        -1.570796326794897
      </pose>
      <size>1 1 5.0</size>
    </plugin>

    <!-- Bling -->
    <include>
      <name>bling_3</name>
      <pose>
      3.6925514593052027
      -1.315978101833501
      0
      0
      0
      -2.356194490192345
      </pose>
      <uri>model://mars_rock_3</uri>
    </include>


    <!-- Walkway -->
    <include>
      <name>walkway_3</name>
      <pose>
      2.914734
      0.5394700919999995
      -0.052151
      0
      0
      -0.7853981633974485
      </pose>
      <uri>model://walkway_metal_straight</uri>
    </include>


    <!-- Bling -->
    <include>
      <name>bling_4</name>
      <pose>
      4.275207447002918
      0.25662737952538023
      0
      0
      0
      -2.3561944901923453
      </pose>
      <uri>model://mars_rock_1</uri>
    </include>


    <!-- Bling -->
    <include>
      <name>bling_5</name>
      <pose>
      2.136916540694798
      2.3949182858335005
      0
      0
      0
      0.7853981633974481
      </pose>
      <uri>model://mars_rock_3</uri>
    </include>


    <!-- Final box 1 -->
    <include>
      <name>walkway_4</name>
      <pose>
      5.069995469056598
      2.694731561056596
      -0.052151
      0
      0
      -2.3561944901923453
      </pose>
      <uri>model://walkway_finish_opposite</uri>
    </include>


    <!-- Checkpoint 4 - Box plugin -->
    <plugin name="boxT1CP4" filename="libBoxContainsPlugin.so">
      <entity>valkyrie</entity>
      <namespace>task1/checkpoint4</namespace>
      <pose>
        5.069995469056598
        2.694731561056596
        2.5
        0
        0
        -2.3561944901923453
      </pose>
      <size>3.048 3.048 5.0</size>
    </plugin>

    <!-- Bling -->
    <include>
      <name>bling_6</name>
      <pose>
      6.430468916059515
      1.334258114053678
      0
      0
      0
      -2.3561944901923453
      </pose>
      <uri>model://mars_crate</uri>
    </include>


    <!-- Bling -->
    <include>
      <name>bling_7</name>
      <pose>
      3.638811343935026
      4.1259156861781685
      0
      0
      0
      0.785398163397448
      </pose>
      <uri>model://mars_rock_2</uri>
    </include>




    <!-- /TASK 1 -->




    <!-- TASK 2 -->



    <!-- Task 2 start - Box plugin -->


    <plugin name="boxT2Start" filename="libBoxContainsPlugin.so">
      <entity>valkyrie</entity>
      <namespace>task2/start</namespace>
      <pose>
        6.50117959417817
        4.125915686178168
        2.5
        0
        0
        -0.7853981633974485
      </pose>
      <size>1.524 1 5.0</size>
    </plugin>

    <!-- Walkway -->
    <include>
      <name>walkway_5</name>
      <pose>
      6.147626203584896
      3.772362295584894
      -0.052151
      0
      0
      -0.7853981633974485
      </pose>
      <uri>model://walkway_metal_straight</uri>
    </include>


    <!-- Walkway -->
    <include>
      <name>walkway_6</name>
      <pose>
      7.763551809732567
      6.1512138223336255
      -0.052151
      0
      0
      3.141592653589793
      </pose>
      <uri>model://walkway_metal_45</uri>
    </include>


    <!-- Rover -->


    <include>
      <pose>
        13.025551809732567
        5.389213822333624
        0
        0
        0
        1.5707963267948961
      </pose>
      <uri>model://mars_explorer</uri>
    </include>

    <!-- Solar panel -->




<model name="solar_panel">

  <pose>
    8.325551809732568
    5.389213822333625
    0.46
    0
    0
    1.231180595062432
  </pose>

  <link name="base">

    <inertial>
      <pose>
      0
      0
      0.04
      0
      0
      0
      </pose>
      <inertia>
        <ixx>0.002500000000000001</ixx>
        <iyy>0.03346720000000001</iyy>
        <izz>0.03496720000000001</izz>
      </inertia>
      <mass>2.4000000000000004</mass>
    </inertial>


    <collision name="collision">
      <geometry>
        <mesh>
          <uri>model://solar_panel/meshes/solar_panel.obj</uri>
          <submesh>
            <name>Base</name>
          </submesh>
          <scale>0.001 0.001 0.001</scale>
        </mesh>
      </geometry>
      <surface>
        <contact>
          <ode>
            <kp>1000000.0</kp>
            <kd>1</kd>
            <max_vel>0.1</max_vel>
            <min_depth>0.0015</min_depth>
          </ode>
        </contact>
      </surface>
    </collision>
    <visual name="visual">
      <geometry>
        <mesh>
          <uri>model://solar_panel/meshes/solar_panel.obj</uri>
          <submesh>
            <name>Base</name>
          </submesh>
          <scale>0.001 0.001 0.001</scale>
        </mesh>
      </geometry>
    </visual>

    <sensor name="base_sensor" type="contact">
      <contact>
        <collision>collision</collision>
      </contact>
    </sensor>

  </link>

  <link name="panel_01">

    <inertial>
      <pose>
      0
      0.05
      0.24
      0
      0
      0
      </pose>
      <inertia>
        <ixx>0.0014224500000000005</ixx>
        <iyy>0.003471650000000001</iyy>
        <izz>0.0020717000000000005</izz>
      </inertia>
      <mass>0.15000000000000002</mass>
    </inertial>


    <collision name="panel_collision">
      <geometry>
        <mesh>
          <uri>model://solar_panel/meshes/solar_panel.obj</uri>
          <submesh>
            <name>Panel_Large_01</name>
          </submesh>
          <scale>0.001 0.001 0.001</scale>
        </mesh>
      </geometry>
      <surface>
        <contact>
          <ode>
            <kp>1000000.0</kp>
            <kd>1</kd>
            <max_vel>0.1</max_vel>
            <min_depth>0.0015</min_depth>
          </ode>
        </contact>
      </surface>
    </collision>
    <visual name="panel_visual">
      <geometry>
        <mesh>
          <uri>model://solar_panel/meshes/solar_panel.obj</uri>
          <submesh>
            <name>Panel_Large_01</name>
          </submesh>
          <scale>0.001 0.001 0.001</scale>
        </mesh>
      </geometry>
    </visual>
    <collision name="button_housing_collision">
      <geometry>
        <mesh>
          <uri>model://solar_panel/meshes/solar_panel.obj</uri>
          <submesh>
            <name>ButtonHousing</name>
          </submesh>
          <scale>0.001 0.001 0.001</scale>
        </mesh>
      </geometry>
      <surface>
        <contact>
          <ode>
            <kp>1000000.0</kp>
            <kd>1</kd>
            <max_vel>0.1</max_vel>
            <min_depth>0.0015</min_depth>
          </ode>
        </contact>
      </surface>
    </collision>
    <visual name="button_housing_visual">
      <geometry>
        <mesh>
          <uri>model://solar_panel/meshes/solar_panel.obj</uri>
          <submesh>
            <name>ButtonHousing</name>
          </submesh>
          <scale>0.001 0.001 0.001</scale>
        </mesh>
      </geometry>
    </visual>

    <sensor name="panel1_sensor" type="contact">
      <contact>
        <collision>panel_collision</collision>
      </contact>
    </sensor>

  </link>


  <link name="panel_02">

    <inertial>
      <pose>
      0
      -0.05
      0.24
      0
      0
      0
      </pose>
      <inertia>
        <ixx>0.0014224500000000005</ixx>
        <iyy>0.003471650000000001</iyy>
        <izz>0.0020717000000000005</izz>
      </inertia>
      <mass>0.15000000000000002</mass>
    </inertial>


    <collision name="collision">
      <geometry>
        <mesh>
          <uri>model://solar_panel/meshes/solar_panel.obj</uri>
          <submesh>
            <name>Panel_Large_02</name>
          </submesh>
          <scale>0.001 0.001 0.001</scale>
        </mesh>
      </geometry>
      <surface>
        <contact>
          <ode>
            <kp>1000000.0</kp>
            <kd>1</kd>
            <max_vel>0.1</max_vel>
            <min_depth>0.0015</min_depth>
          </ode>
        </contact>
      </surface>
    </collision>
    <visual name="visual">
      <geometry>
        <mesh>
          <uri>model://solar_panel/meshes/solar_panel.obj</uri>
          <submesh>
            <name>Panel_Large_02</name>
          </submesh>
          <scale>0.001 0.001 0.001</scale>
        </mesh>
      </geometry>
    </visual>

    <collision name="outlet">
      <pose>0.13675 0 0.369 1.5707963267948966 0 0</pose>
      <geometry>
        <cylinder>
          <length>0.003222</length>
          <radius>0.018693</radius>
        </cylinder>
      </geometry>
      <surface>
        <contact>
          <ode>
            <kp>1000000.0</kp>
            <kd>1</kd>
            <max_vel>0.1</max_vel>
            <min_depth>0.0015</min_depth>
          </ode>
        </contact>
      </surface>
    </collision>

    <sensor name="panel2_sensor" type="contact">
      <contact>
        <collision>collision</collision>
      </contact>
    </sensor>

    <sensor name="outlet_sensor" type="contact">
      <contact>
        <collision>outlet</collision>
      </contact>
    </sensor>

  </link>

  <link name="panel_small_01">

    <pose>0.2 0.03 0.2 0 0 0</pose>

    <inertial>
      <pose>
      -0.1
      -0.015
      0.005
      0
      0
      0
      </pose>
      <inertia>
        <ixx>0.000291125</ixx>
        <iyy>0.00048800000000000004</iyy>
        <izz>0.00020312500000000004</izz>
      </inertia>
      <mass>0.06</mass>
    </inertial>


    <collision name="collision">
      <pose>-0.2 -0.03 -0.2 0 0 0</pose>
      <geometry>
        <mesh>
          <uri>model://solar_panel/meshes/solar_panel.obj</uri>
          <submesh>
            <name>Panel_Small_01</name>
          </submesh>
          <scale>0.001 0.001 0.001</scale>
        </mesh>
      </geometry>
      <surface>
        <contact>
          <ode>
            <kp>1000000.0</kp>
            <kd>1</kd>
            <max_vel>0.1</max_vel>
            <min_depth>0.0015</min_depth>
          </ode>
        </contact>
      </surface>
    </collision>
    <visual name="visual">
      <pose>-0.2 -0.03 -0.2 0 0 0</pose>
      <geometry>
        <mesh>
          <uri>model://solar_panel/meshes/solar_panel.obj</uri>
          <submesh>
            <name>Panel_Small_01</name>
          </submesh>
          <scale>0.001 0.001 0.001</scale>
        </mesh>
      </geometry>
    </visual>
  </link>

  <link name="panel_small_02">

    <pose>0.2 -0.03 0.2 0 0 0</pose>

    <inertial>
      <pose>
      -0.1
      0.015
      0.005
      0
      0
      0
      </pose>
      <inertia>
        <ixx>0.000291125</ixx>
        <iyy>0.00048800000000000004</iyy>
        <izz>0.00020312500000000004</izz>
      </inertia>
      <mass>0.06</mass>
    </inertial>


    <collision name="collision">
      <pose>-0.2 0.03 -0.2 0 0 0</pose>
      <geometry>
        <mesh>
          <uri>model://solar_panel/meshes/solar_panel.obj</uri>
          <submesh>
            <name>Panel_Small_02</name>
          </submesh>
          <scale>0.001 0.001 0.001</scale>
        </mesh>
      </geometry>
      <surface>
        <contact>
          <ode>
            <kp>1000000.0</kp>
            <kd>1</kd>
            <max_vel>0.1</max_vel>
            <min_depth>0.0015</min_depth>
          </ode>
        </contact>
      </surface>
    </collision>
    <visual name="visual">
      <pose>-0.2 0.03 -0.2 0 0 0</pose>
      <geometry>
        <mesh>
          <uri>model://solar_panel/meshes/solar_panel.obj</uri>
          <submesh>
            <name>Panel_Small_02</name>
          </submesh>
          <scale>0.001 0.001 0.001</scale>
        </mesh>
      </geometry>
    </visual>
  </link>

  <link name="panel_small_03">

    <pose>-0.2 0.03 0.2 0 0 0</pose>

    <inertial>
      <pose>
      0.1
      -0.015
      0.005
      0
      0
      0
      </pose>
      <inertia>
        <ixx>0.000291125</ixx>
        <iyy>0.00048800000000000004</iyy>
        <izz>0.00020312500000000004</izz>
      </inertia>
      <mass>0.06</mass>
    </inertial>


    <collision name="collision">
      <pose>0.2 -0.03 -0.2 0 0 0</pose>
      <geometry>
        <mesh>
          <uri>model://solar_panel/meshes/solar_panel.obj</uri>
          <submesh>
            <name>Panel_Small_03</name>
          </submesh>
          <scale>0.001 0.001 0.001</scale>
        </mesh>
      </geometry>
      <surface>
        <contact>
          <ode>
            <kp>1000000.0</kp>
            <kd>1</kd>
            <max_vel>0.1</max_vel>
            <min_depth>0.0015</min_depth>
          </ode>
        </contact>
      </surface>
    </collision>
    <visual name="visual">
      <pose>0.2 -0.03 -0.2 0 0 0</pose>
      <geometry>
        <mesh>
          <uri>model://solar_panel/meshes/solar_panel.obj</uri>
          <submesh>
            <name>Panel_Small_03</name>
          </submesh>
          <scale>0.001 0.001 0.001</scale>
        </mesh>
      </geometry>
    </visual>
  </link>

  <link name="panel_small_04">

    <pose>-0.2 -0.03 0.2 0 0 0</pose>

    <inertial>
      <pose>
      0.1
      0.015
      0.005
      0
      0
      0
      </pose>
      <inertia>
        <ixx>0.000291125</ixx>
        <iyy>0.00048800000000000004</iyy>
        <izz>0.00020312500000000004</izz>
      </inertia>
      <mass>0.06</mass>
    </inertial>


    <collision name="collision">
      <pose>0.2 0.03 -0.2 0 0 0</pose>
      <geometry>
        <mesh>
          <uri>model://solar_panel/meshes/solar_panel.obj</uri>
          <submesh>
            <name>Panel_Small_04</name>
          </submesh>
          <scale>0.001 0.001 0.001</scale>
        </mesh>
      </geometry>
      <surface>
        <contact>
          <ode>
            <kp>1000000.0</kp>
            <kd>1</kd>
            <max_vel>0.1</max_vel>
            <min_depth>0.0015</min_depth>
          </ode>
        </contact>
      </surface>
    </collision>
    <visual name="visual">
      <pose>0.2 0.03 -0.2 0 0 0</pose>
      <geometry>
        <mesh>
          <uri>model://solar_panel/meshes/solar_panel.obj</uri>
          <submesh>
            <name>Panel_Small_04</name>
          </submesh>
          <scale>0.001 0.001 0.001</scale>
        </mesh>
      </geometry>
    </visual>
  </link>


  <link name="button">

    <pose>-0.155 0 0.4 0 0 0</pose>

    <inertial>
      <pose>
      0
      0
      0.017
      0
      0
      0
      </pose>
      <inertia>
        <ixx>2.9000000000000004e-05</ixx>
        <iyy>2.9000000000000004e-05</iyy>
        <izz>4.9000000000000005e-05</izz>
      </inertia>
      <mass>0.06</mass>
    </inertial>


    <collision name="collision">
      <pose>0.155 0 -0.4 0 0 0</pose>
      <geometry>
        <mesh>
          <uri>model://solar_panel/meshes/solar_panel.obj</uri>
          <submesh>
            <name>Button</name>
          </submesh>
          <scale>0.001 0.001 0.001</scale>
        </mesh>
      </geometry>
      <surface>
        <contact>
          <ode>
            <kp>1000000.0</kp>
            <kd>1</kd>
            <max_vel>0.1</max_vel>
            <min_depth>0.0015</min_depth>
          </ode>
        </contact>
      </surface>
    </collision>
    <visual name="visual">
      <pose>0.155 0 -0.4 0 0 0</pose>
      <geometry>
        <mesh>
          <uri>model://solar_panel/meshes/solar_panel.obj</uri>
          <submesh>
            <name>Button</name>
          </submesh>
          <scale>0.001 0.001 0.001</scale>
        </mesh>
      </geometry>
    </visual>

    <sensor name="button_contact" type="contact">
      <contact>
        <collision>collision</collision>
      </contact>
    </sensor>

  </link>



  <joint name="base_panel_01" type="revolute">
    <pose>0 0.0455 0.095 0 0 0</pose>
    <parent>base</parent>
    <child>panel_01</child>
    <axis>
      <xyz>1 0 0</xyz>
      <limit>
       <lower>-1.5707963267948966</lower>
       <upper>0</upper>
      </limit>
      <dynamics>
        <damping>0.1</damping>
      </dynamics>
    </axis>
  </joint>

  <joint name="base_panel_02" type="revolute">
    <pose>0 -0.0455 0.095 0 0 0</pose>
    <parent>base</parent>
    <child>panel_02</child>
    <axis>
      <xyz>1 0 0</xyz>
      <limit>
       <lower>0</lower>
       <upper>1.5707963267948966</upper>
      </limit>
      <dynamics>
        <damping>0.1</damping>
      </dynamics>
    </axis>
  </joint>

  <joint name="panel_01_panel_small_01" type="revolute">
    <parent>panel_01</parent>
    <child>panel_small_01</child>
    <axis>
      <xyz>0 0 1</xyz>
      <limit>
       <lower>0</lower>
       <upper>3.141592653589793</upper>
      </limit>
      <dynamics>
        <damping>0.1</damping>
      </dynamics>
    </axis>
  </joint>

  <joint name="panel_02_panel_small_02" type="revolute">
    <parent>panel_02</parent>
    <child>panel_small_02</child>
    <axis>
      <xyz>0 0 1</xyz>
      <limit>
       <lower>-3.141592653589793</lower>
       <upper>0</upper>
      </limit>
      <dynamics>
        <damping>0.1</damping>
      </dynamics>
    </axis>
  </joint>

  <joint name="panel_01_panel_small_03" type="revolute">
    <parent>panel_01</parent>
    <child>panel_small_03</child>
    <axis>
      <xyz>0 0 1</xyz>
      <limit>
       <lower>-3.141592653589793</lower>
       <upper>0</upper>
      </limit>
      <dynamics>
        <damping>0.1</damping>
      </dynamics>
    </axis>
  </joint>

  <joint name="panel_02_panel_small_04" type="revolute">
    <parent>panel_02</parent>
    <child>panel_small_04</child>
    <axis>
      <xyz>0 0 1</xyz>
      <limit>
       <lower>0</lower>
       <upper>3.141592653589793</upper>
      </limit>
      <dynamics>
        <damping>0.1</damping>
      </dynamics>
    </axis>
  </joint>


  <joint name="button" type="prismatic">
    <pose>0 0 0.005 0 0 0</pose>
    <parent>panel_01</parent>
    <child>button</child>
    <axis>
      <xyz>0 0 1</xyz>
      <limit>
       <lower>-0.005</lower>
       <upper>0</upper>
      </limit>
      <dynamics>
        <damping>10</damping>
        <spring_stiffness>1000</spring_stiffness>
        <spring_reference>0</spring_reference>
      </dynamics>
    </axis>
  </joint>

  <joint name="lock_1" type="fixed">
    <parent>panel_01</parent>
    <child>panel_02</child>
  </joint>

  <joint name="lock_2" type="fixed">
    <parent>panel_small_01</parent>
    <child>panel_small_03</child>
  </joint>

  <joint name="lock_3" type="fixed">
    <parent>panel_small_02</parent>
    <child>panel_small_04</child>
  </joint>

  <plugin name="solar_panel_plugin" filename="libSolarPanelPlugin.so">
  </plugin>

  <plugin name="touch_valkyrie_panel" filename="libTouchPlugin.so">
    <sensor>base_sensor</sensor>
    <sensor>panel1_sensor</sensor>
    <sensor>panel2_sensor</sensor>
    <target>valkyrie</target>
    <time>0.5</time>
    <namespace>task2/checkpoint1</namespace>
  </plugin>

</model>


    <!-- Bling -->


    <!-- Walkway -->
    <include>
      <name>walkway_7</name>
      <pose>
      7.763551809732567
      6.1512138223336255
      -0.052151
      0
      0
      -3.4450928483976665e-16
      </pose>
      <uri>model://walkway_metal_straight</uri>
    </include>


    <!-- Walkway -->
    <include>
      <name>walkway_8</name>
      <pose>
      7.763551809732568
      7.6752138223336255
      -0.052151
      0
      0
      -3.4450928483976665e-16
      </pose>
      <uri>model://walkway_metal_45</uri>
    </include>


    <!-- Bling -->
    <include>
      <name>bling_8</name>
      <pose>
      6.5882663847833305
      9.597259247282864
      0
      0
      0
      1.5707963267948961
      </pose>
      <uri>model://mars_crate_long</uri>
    </include>


    <!-- Bling -->
    <include>
      <name>bling_9</name>
      <pose>
      6.601551809732568
      8.437213822333625
      0
      0
      0
      1.5707963267948961
      </pose>
      <uri>model://mars_rock_1</uri>
    </include>


    <!-- Walkway -->
    <include>
      <name>walkway_9</name>
      <pose>
      8.303021901732569
      8.975947822333625
      -0.052151
      0
      0
      -0.7853981633974485
      </pose>
      <uri>model://walkway_metal_straight</uri>
    </include>


    <!-- Solar Array -->


    <include>
      <pose>
        7.914113172079968
        10.442487286514524
        0.2
        0
        0
        0.7853981633974481
      </pose>
      <uri>model://solar_array</uri>
    </include>

    <!-- Cable -->




<model name="solar_panel_cable">

  <self_collide>true</self_collide>

  <pose>
    7.772691815842658
    11.149594067701072
    1.05
    0
    0
    -0.7853981633974485
  </pose>

  <link name="link_0">
    <inertial>
      <mass>0.05</mass>
      <inertia>
        <ixx>0.0001</ixx>
        <iyy>0.0001</iyy>
        <izz>0.0001</izz>
      </inertia>
    </inertial>
    <visual name="visual">
      <geometry>
        <sphere>
          <radius>0.02</radius>
        </sphere>
      </geometry>
      <material>
  <ambient>0 0 0 1</ambient>
  <emissive>0 0 0 1</emissive>
  <diffuse>0 0 0 1</diffuse>
  <specular>1 1 1 1</specular>
</material>

    </visual>
  </link>



  <link name="link_1">
    <pose>0.0 0 0 0 1.5707963267948966 0.9424777960769379</pose>
    <inertial>
      <pose>0 0 0.05 0 0 0</pose>
      <mass>0.05</mass>
      <inertia>
        <ixx>0.0001</ixx>
        <iyy>0.0001</iyy>
        <izz>0.0001</izz>
      </inertia>
    </inertial>

    <collision name="cylinder">
      <pose>0 0 0.05 0 0 0</pose>
      <geometry>
        <cylinder>
          <length>0.1</length>
          <radius>0.01</radius>
        </cylinder>
      </geometry>
      <surface>
        <contact>
          <ode>
            <kp>1e5</kp>
            <kd>1</kd>
            <max_vel>0.1</max_vel>
            <min_depth>0.0015</min_depth>
          </ode>
        </contact>
        <friction>
          <ode>
            <mu>1.0</mu>
            <mu2>1.0</mu2>
          </ode>
        </friction>
      </surface>
    </collision>
    <visual name="cylinder">
      <pose>0 0 0.05 0 0 0</pose>
      <geometry>
        <cylinder>
          <length>0.1</length>
          <radius>0.01</radius>
        </cylinder>
      </geometry>
      <material>
  <ambient>0 0 0 1</ambient>
  <emissive>0 0 0 1</emissive>
  <diffuse>0 0 0 1</diffuse>
  <specular>1 1 1 1</specular>
</material>

    </visual>
    <collision name="sphere">
      <geometry>
        <sphere>
          <radius>0.01</radius>
        </sphere>
      </geometry>
      <surface>
        <contact>
          <ode>
            <kp>1e5</kp>
            <kd>1</kd>
            <max_vel>0.1</max_vel>
            <min_depth>0.0015</min_depth>
          </ode>
        </contact>
        <friction>
          <ode>
            <mu>1.0</mu>
            <mu2>1.0</mu2>
          </ode>
        </friction>
      </surface>
    </collision>

    <visual name="sphere">
      <geometry>
        <sphere>
          <radius>0.01</radius>
        </sphere>
      </geometry>
      <material>
  <ambient>0 0 0 1</ambient>
  <emissive>0 0 0 1</emissive>
  <diffuse>0 0 0 1</diffuse>
  <specular>1 1 1 1</specular>
</material>

    </visual>



  </link>

  <joint name="joint_1" type="universal">
    <child>link_1</child>
    <parent>link_0</parent>
    <axis>
      <xyz>0 1 0</xyz>
      <limit>
        <lower>-1.5707963267948966</lower>
        <upper>1.5707963267948966</upper>
      </limit>
    </axis>
    <axis2>
      <xyz>-1 0 0</xyz>
      <limit>
        <lower>-1.5707963267948966</lower>
        <upper>1.5707963267948966</upper>
      </limit>
    </axis2>
    <physics>
      <ode>
        <cfm_damping>1</cfm_damping>
      </ode>
    </physics>
  </joint>



  <link name="link_2">
    <pose>0.058778525229247314 0.08090169943749476 0 0 1.5707963267948966 -0.9424777960769379</pose>
    <inertial>
      <pose>0 0 0.05 0 0 0</pose>
      <mass>0.05</mass>
      <inertia>
        <ixx>0.0001</ixx>
        <iyy>0.0001</iyy>
        <izz>0.0001</izz>
      </inertia>
    </inertial>

    <collision name="cylinder">
      <pose>0 0 0.05 0 0 0</pose>
      <geometry>
        <cylinder>
          <length>0.1</length>
          <radius>0.01</radius>
        </cylinder>
      </geometry>
      <surface>
        <contact>
          <ode>
            <kp>1e5</kp>
            <kd>1</kd>
            <max_vel>0.1</max_vel>
            <min_depth>0.0015</min_depth>
          </ode>
        </contact>
        <friction>
          <ode>
            <mu>1.0</mu>
            <mu2>1.0</mu2>
          </ode>
        </friction>
      </surface>
    </collision>
    <visual name="cylinder">
      <pose>0 0 0.05 0 0 0</pose>
      <geometry>
        <cylinder>
          <length>0.1</length>
          <radius>0.01</radius>
        </cylinder>
      </geometry>
      <material>
  <ambient>0 0 0 1</ambient>
  <emissive>0 0 0 1</emissive>
  <diffuse>0 0 0 1</diffuse>
  <specular>1 1 1 1</specular>
</material>

    </visual>
    <collision name="sphere">
      <geometry>
        <sphere>
          <radius>0.01</radius>
        </sphere>
      </geometry>
      <surface>
        <contact>
          <ode>
            <kp>1e5</kp>
            <kd>1</kd>
            <max_vel>0.1</max_vel>
            <min_depth>0.0015</min_depth>
          </ode>
        </contact>
        <friction>
          <ode>
            <mu>1.0</mu>
            <mu2>1.0</mu2>
          </ode>
        </friction>
      </surface>
    </collision>

    <visual name="sphere">
      <geometry>
        <sphere>
          <radius>0.01</radius>
        </sphere>
      </geometry>
      <material>
  <ambient>0 0 0 1</ambient>
  <emissive>0 0 0 1</emissive>
  <diffuse>0 0 0 1</diffuse>
  <specular>1 1 1 1</specular>
</material>

    </visual>



  </link>

  <joint name="joint_2" type="universal">
    <child>link_2</child>
    <parent>link_1</parent>
    <axis>
      <xyz>0 1 0</xyz>
      <limit>
        <lower>-1.5707963267948966</lower>
        <upper>1.5707963267948966</upper>
      </limit>
    </axis>
    <axis2>
      <xyz>-1 0 0</xyz>
      <limit>
        <lower>-1.5707963267948966</lower>
        <upper>1.5707963267948966</upper>
      </limit>
    </axis2>
    <physics>
      <ode>
        <cfm_damping>1</cfm_damping>
      </ode>
    </physics>
  </joint>



  <link name="link_3">
    <pose>0.11755705045849463 0 0 0 1.5707963267948966 -0.9424777960769379</pose>
    <inertial>
      <pose>0 0 0.05 0 0 0</pose>
      <mass>0.05</mass>
      <inertia>
        <ixx>0.0001</ixx>
        <iyy>0.0001</iyy>
        <izz>0.0001</izz>
      </inertia>
    </inertial>

    <collision name="cylinder">
      <pose>0 0 0.05 0 0 0</pose>
      <geometry>
        <cylinder>
          <length>0.1</length>
          <radius>0.01</radius>
        </cylinder>
      </geometry>
      <surface>
        <contact>
          <ode>
            <kp>1e5</kp>
            <kd>1</kd>
            <max_vel>0.1</max_vel>
            <min_depth>0.0015</min_depth>
          </ode>
        </contact>
        <friction>
          <ode>
            <mu>1.0</mu>
            <mu2>1.0</mu2>
          </ode>
        </friction>
      </surface>
    </collision>
    <visual name="cylinder">
      <pose>0 0 0.05 0 0 0</pose>
      <geometry>
        <cylinder>
          <length>0.1</length>
          <radius>0.01</radius>
        </cylinder>
      </geometry>
      <material>
  <ambient>0 0 0 1</ambient>
  <emissive>0 0 0 1</emissive>
  <diffuse>0 0 0 1</diffuse>
  <specular>1 1 1 1</specular>
</material>

    </visual>
    <collision name="sphere">
      <geometry>
        <sphere>
          <radius>0.01</radius>
        </sphere>
      </geometry>
      <surface>
        <contact>
          <ode>
            <kp>1e5</kp>
            <kd>1</kd>
            <max_vel>0.1</max_vel>
            <min_depth>0.0015</min_depth>
          </ode>
        </contact>
        <friction>
          <ode>
            <mu>1.0</mu>
            <mu2>1.0</mu2>
          </ode>
        </friction>
      </surface>
    </collision>

    <visual name="sphere">
      <geometry>
        <sphere>
          <radius>0.01</radius>
        </sphere>
      </geometry>
      <material>
  <ambient>0 0 0 1</ambient>
  <emissive>0 0 0 1</emissive>
  <diffuse>0 0 0 1</diffuse>
  <specular>1 1 1 1</specular>
</material>

    </visual>



  </link>

  <joint name="joint_3" type="universal">
    <child>link_3</child>
    <parent>link_2</parent>
    <axis>
      <xyz>0 1 0</xyz>
      <limit>
        <lower>-1.5707963267948966</lower>
        <upper>1.5707963267948966</upper>
      </limit>
    </axis>
    <axis2>
      <xyz>-1 0 0</xyz>
      <limit>
        <lower>-1.5707963267948966</lower>
        <upper>1.5707963267948966</upper>
      </limit>
    </axis2>
    <physics>
      <ode>
        <cfm_damping>1</cfm_damping>
      </ode>
    </physics>
  </joint>



  <link name="link_4">
    <pose>0.17633557568774197 -0.08090169943749476 0 0 1.5707963267948966 0.9424777960769379</pose>
    <inertial>
      <pose>0 0 0.05 0 0 0</pose>
      <mass>0.05</mass>
      <inertia>
        <ixx>0.0001</ixx>
        <iyy>0.0001</iyy>
        <izz>0.0001</izz>
      </inertia>
    </inertial>

    <collision name="cylinder">
      <pose>0 0 0.05 0 0 0</pose>
      <geometry>
        <cylinder>
          <length>0.1</length>
          <radius>0.01</radius>
        </cylinder>
      </geometry>
      <surface>
        <contact>
          <ode>
            <kp>1e5</kp>
            <kd>1</kd>
            <max_vel>0.1</max_vel>
            <min_depth>0.0015</min_depth>
          </ode>
        </contact>
        <friction>
          <ode>
            <mu>1.0</mu>
            <mu2>1.0</mu2>
          </ode>
        </friction>
      </surface>
    </collision>
    <visual name="cylinder">
      <pose>0 0 0.05 0 0 0</pose>
      <geometry>
        <cylinder>
          <length>0.1</length>
          <radius>0.01</radius>
        </cylinder>
      </geometry>
      <material>
  <ambient>0 0 0 1</ambient>
  <emissive>0 0 0 1</emissive>
  <diffuse>0 0 0 1</diffuse>
  <specular>1 1 1 1</specular>
</material>

    </visual>
    <collision name="sphere">
      <geometry>
        <sphere>
          <radius>0.01</radius>
        </sphere>
      </geometry>
      <surface>
        <contact>
          <ode>
            <kp>1e5</kp>
            <kd>1</kd>
            <max_vel>0.1</max_vel>
            <min_depth>0.0015</min_depth>
          </ode>
        </contact>
        <friction>
          <ode>
            <mu>1.0</mu>
            <mu2>1.0</mu2>
          </ode>
        </friction>
      </surface>
    </collision>

    <visual name="sphere">
      <geometry>
        <sphere>
          <radius>0.01</radius>
        </sphere>
      </geometry>
      <material>
  <ambient>0 0 0 1</ambient>
  <emissive>0 0 0 1</emissive>
  <diffuse>0 0 0 1</diffuse>
  <specular>1 1 1 1</specular>
</material>

    </visual>



  </link>

  <joint name="joint_4" type="universal">
    <child>link_4</child>
    <parent>link_3</parent>
    <axis>
      <xyz>0 1 0</xyz>
      <limit>
        <lower>-1.5707963267948966</lower>
        <upper>1.5707963267948966</upper>
      </limit>
    </axis>
    <axis2>
      <xyz>-1 0 0</xyz>
      <limit>
        <lower>-1.5707963267948966</lower>
        <upper>1.5707963267948966</upper>
      </limit>
    </axis2>
    <physics>
      <ode>
        <cfm_damping>1</cfm_damping>
      </ode>
    </physics>
  </joint>



  <link name="link_5">
    <pose>0.23511410091698925 0 0 0 1.5707963267948966 0.9424777960769379</pose>
    <inertial>
      <pose>0 0 0.05 0 0 0</pose>
      <mass>0.05</mass>
      <inertia>
        <ixx>0.0001</ixx>
        <iyy>0.0001</iyy>
        <izz>0.0001</izz>
      </inertia>
    </inertial>

    <collision name="cylinder">
      <pose>0 0 0.05 0 0 0</pose>
      <geometry>
        <cylinder>
          <length>0.1</length>
          <radius>0.01</radius>
        </cylinder>
      </geometry>
      <surface>
        <contact>
          <ode>
            <kp>1e5</kp>
            <kd>1</kd>
            <max_vel>0.1</max_vel>
            <min_depth>0.0015</min_depth>
          </ode>
        </contact>
        <friction>
          <ode>
            <mu>1.0</mu>
            <mu2>1.0</mu2>
          </ode>
        </friction>
      </surface>
    </collision>
    <visual name="cylinder">
      <pose>0 0 0.05 0 0 0</pose>
      <geometry>
        <cylinder>
          <length>0.1</length>
          <radius>0.01</radius>
        </cylinder>
      </geometry>
      <material>
  <ambient>0 0 0 1</ambient>
  <emissive>0 0 0 1</emissive>
  <diffuse>0 0 0 1</diffuse>
  <specular>1 1 1 1</specular>
</material>

    </visual>
    <collision name="sphere">
      <geometry>
        <sphere>
          <radius>0.01</radius>
        </sphere>
      </geometry>
      <surface>
        <contact>
          <ode>
            <kp>1e5</kp>
            <kd>1</kd>
            <max_vel>0.1</max_vel>
            <min_depth>0.0015</min_depth>
          </ode>
        </contact>
        <friction>
          <ode>
            <mu>1.0</mu>
            <mu2>1.0</mu2>
          </ode>
        </friction>
      </surface>
    </collision>

    <visual name="sphere">
      <geometry>
        <sphere>
          <radius>0.01</radius>
        </sphere>
      </geometry>
      <material>
  <ambient>0 0 0 1</ambient>
  <emissive>0 0 0 1</emissive>
  <diffuse>0 0 0 1</diffuse>
  <specular>1 1 1 1</specular>
</material>

    </visual>



  </link>

  <joint name="joint_5" type="universal">
    <child>link_5</child>
    <parent>link_4</parent>
    <axis>
      <xyz>0 1 0</xyz>
      <limit>
        <lower>-1.5707963267948966</lower>
        <upper>1.5707963267948966</upper>
      </limit>
    </axis>
    <axis2>
      <xyz>-1 0 0</xyz>
      <limit>
        <lower>-1.5707963267948966</lower>
        <upper>1.5707963267948966</upper>
      </limit>
    </axis2>
    <physics>
      <ode>
        <cfm_damping>1</cfm_damping>
      </ode>
    </physics>
  </joint>



  <link name="link_6">
    <pose>0.29389262614623657 0.08090169943749476 0 0 1.5707963267948966 -0.9424777960769379</pose>
    <inertial>
      <pose>0 0 0.05 0 0 0</pose>
      <mass>0.05</mass>
      <inertia>
        <ixx>0.0001</ixx>
        <iyy>0.0001</iyy>
        <izz>0.0001</izz>
      </inertia>
    </inertial>

    <collision name="cylinder">
      <pose>0 0 0.05 0 0 0</pose>
      <geometry>
        <cylinder>
          <length>0.1</length>
          <radius>0.01</radius>
        </cylinder>
      </geometry>
      <surface>
        <contact>
          <ode>
            <kp>1e5</kp>
            <kd>1</kd>
            <max_vel>0.1</max_vel>
            <min_depth>0.0015</min_depth>
          </ode>
        </contact>
        <friction>
          <ode>
            <mu>1.0</mu>
            <mu2>1.0</mu2>
          </ode>
        </friction>
      </surface>
    </collision>
    <visual name="cylinder">
      <pose>0 0 0.05 0 0 0</pose>
      <geometry>
        <cylinder>
          <length>0.1</length>
          <radius>0.01</radius>
        </cylinder>
      </geometry>
      <material>
  <ambient>0 0 0 1</ambient>
  <emissive>0 0 0 1</emissive>
  <diffuse>0 0 0 1</diffuse>
  <specular>1 1 1 1</specular>
</material>

    </visual>
    <collision name="sphere">
      <geometry>
        <sphere>
          <radius>0.01</radius>
        </sphere>
      </geometry>
      <surface>
        <contact>
          <ode>
            <kp>1e5</kp>
            <kd>1</kd>
            <max_vel>0.1</max_vel>
            <min_depth>0.0015</min_depth>
          </ode>
        </contact>
        <friction>
          <ode>
            <mu>1.0</mu>
            <mu2>1.0</mu2>
          </ode>
        </friction>
      </surface>
    </collision>

    <visual name="sphere">
      <geometry>
        <sphere>
          <radius>0.01</radius>
        </sphere>
      </geometry>
      <material>
  <ambient>0 0 0 1</ambient>
  <emissive>0 0 0 1</emissive>
  <diffuse>0 0 0 1</diffuse>
  <specular>1 1 1 1</specular>
</material>

    </visual>



  </link>

  <joint name="joint_6" type="universal">
    <child>link_6</child>
    <parent>link_5</parent>
    <axis>
      <xyz>0 1 0</xyz>
      <limit>
        <lower>-1.5707963267948966</lower>
        <upper>1.5707963267948966</upper>
      </limit>
    </axis>
    <axis2>
      <xyz>-1 0 0</xyz>
      <limit>
        <lower>-1.5707963267948966</lower>
        <upper>1.5707963267948966</upper>
      </limit>
    </axis2>
    <physics>
      <ode>
        <cfm_damping>1</cfm_damping>
      </ode>
    </physics>
  </joint>



  <link name="link_7">
    <pose>0.35267115137548394 0 0 0 1.5707963267948966 -0.9424777960769379</pose>
    <inertial>
      <pose>0 0 0.05 0 0 0</pose>
      <mass>0.05</mass>
      <inertia>
        <ixx>0.0001</ixx>
        <iyy>0.0001</iyy>
        <izz>0.0001</izz>
      </inertia>
    </inertial>

    <collision name="cylinder">
      <pose>0 0 0.05 0 0 0</pose>
      <geometry>
        <cylinder>
          <length>0.1</length>
          <radius>0.01</radius>
        </cylinder>
      </geometry>
      <surface>
        <contact>
          <ode>
            <kp>1e5</kp>
            <kd>1</kd>
            <max_vel>0.1</max_vel>
            <min_depth>0.0015</min_depth>
          </ode>
        </contact>
        <friction>
          <ode>
            <mu>1.0</mu>
            <mu2>1.0</mu2>
          </ode>
        </friction>
      </surface>
    </collision>
    <visual name="cylinder">
      <pose>0 0 0.05 0 0 0</pose>
      <geometry>
        <cylinder>
          <length>0.1</length>
          <radius>0.01</radius>
        </cylinder>
      </geometry>
      <material>
  <ambient>0 0 0 1</ambient>
  <emissive>0 0 0 1</emissive>
  <diffuse>0 0 0 1</diffuse>
  <specular>1 1 1 1</specular>
</material>

    </visual>
    <collision name="sphere">
      <geometry>
        <sphere>
          <radius>0.01</radius>
        </sphere>
      </geometry>
      <surface>
        <contact>
          <ode>
            <kp>1e5</kp>
            <kd>1</kd>
            <max_vel>0.1</max_vel>
            <min_depth>0.0015</min_depth>
          </ode>
        </contact>
        <friction>
          <ode>
            <mu>1.0</mu>
            <mu2>1.0</mu2>
          </ode>
        </friction>
      </surface>
    </collision>

    <visual name="sphere">
      <geometry>
        <sphere>
          <radius>0.01</radius>
        </sphere>
      </geometry>
      <material>
  <ambient>0 0 0 1</ambient>
  <emissive>0 0 0 1</emissive>
  <diffuse>0 0 0 1</diffuse>
  <specular>1 1 1 1</specular>
</material>

    </visual>



  </link>

  <joint name="joint_7" type="universal">
    <child>link_7</child>
    <parent>link_6</parent>
    <axis>
      <xyz>0 1 0</xyz>
      <limit>
        <lower>-1.5707963267948966</lower>
        <upper>1.5707963267948966</upper>
      </limit>
    </axis>
    <axis2>
      <xyz>-1 0 0</xyz>
      <limit>
        <lower>-1.5707963267948966</lower>
        <upper>1.5707963267948966</upper>
      </limit>
    </axis2>
    <physics>
      <ode>
        <cfm_damping>1</cfm_damping>
      </ode>
    </physics>
  </joint>



  <link name="link_8">
    <pose>0.41144967660473125 -0.08090169943749476 0 0 1.5707963267948966 0.9424777960769379</pose>
    <inertial>
      <pose>0 0 0.05 0 0 0</pose>
      <mass>0.05</mass>
      <inertia>
        <ixx>0.0001</ixx>
        <iyy>0.0001</iyy>
        <izz>0.0001</izz>
      </inertia>
    </inertial>

    <collision name="cylinder">
      <pose>0 0 0.05 0 0 0</pose>
      <geometry>
        <cylinder>
          <length>0.1</length>
          <radius>0.01</radius>
        </cylinder>
      </geometry>
      <surface>
        <contact>
          <ode>
            <kp>1e5</kp>
            <kd>1</kd>
            <max_vel>0.1</max_vel>
            <min_depth>0.0015</min_depth>
          </ode>
        </contact>
        <friction>
          <ode>
            <mu>1.0</mu>
            <mu2>1.0</mu2>
          </ode>
        </friction>
      </surface>
    </collision>
    <visual name="cylinder">
      <pose>0 0 0.05 0 0 0</pose>
      <geometry>
        <cylinder>
          <length>0.1</length>
          <radius>0.01</radius>
        </cylinder>
      </geometry>
      <material>
  <ambient>0 0 0 1</ambient>
  <emissive>0 0 0 1</emissive>
  <diffuse>0 0 0 1</diffuse>
  <specular>1 1 1 1</specular>
</material>

    </visual>
    <collision name="sphere">
      <geometry>
        <sphere>
          <radius>0.01</radius>
        </sphere>
      </geometry>
      <surface>
        <contact>
          <ode>
            <kp>1e5</kp>
            <kd>1</kd>
            <max_vel>0.1</max_vel>
            <min_depth>0.0015</min_depth>
          </ode>
        </contact>
        <friction>
          <ode>
            <mu>1.0</mu>
            <mu2>1.0</mu2>
          </ode>
        </friction>
      </surface>
    </collision>

    <visual name="sphere">
      <geometry>
        <sphere>
          <radius>0.01</radius>
        </sphere>
      </geometry>
      <material>
  <ambient>0 0 0 1</ambient>
  <emissive>0 0 0 1</emissive>
  <diffuse>0 0 0 1</diffuse>
  <specular>1 1 1 1</specular>
</material>

    </visual>



  </link>

  <joint name="joint_8" type="universal">
    <child>link_8</child>
    <parent>link_7</parent>
    <axis>
      <xyz>0 1 0</xyz>
      <limit>
        <lower>-1.5707963267948966</lower>
        <upper>1.5707963267948966</upper>
      </limit>
    </axis>
    <axis2>
      <xyz>-1 0 0</xyz>
      <limit>
        <lower>-1.5707963267948966</lower>
        <upper>1.5707963267948966</upper>
      </limit>
    </axis2>
    <physics>
      <ode>
        <cfm_damping>1</cfm_damping>
      </ode>
    </physics>
  </joint>



  <link name="link_9">
    <pose>0.4702282018339785 0 0 0 1.5707963267948966 0.9424777960769379</pose>
    <inertial>
      <pose>0 0 0.05 0 0 0</pose>
      <mass>0.05</mass>
      <inertia>
        <ixx>0.0001</ixx>
        <iyy>0.0001</iyy>
        <izz>0.0001</izz>
      </inertia>
    </inertial>

    <collision name="cylinder">
      <pose>0 0 0.05 0 0 0</pose>
      <geometry>
        <cylinder>
          <length>0.1</length>
          <radius>0.01</radius>
        </cylinder>
      </geometry>
      <surface>
        <contact>
          <ode>
            <kp>1e5</kp>
            <kd>1</kd>
            <max_vel>0.1</max_vel>
            <min_depth>0.0015</min_depth>
          </ode>
        </contact>
        <friction>
          <ode>
            <mu>1.0</mu>
            <mu2>1.0</mu2>
          </ode>
        </friction>
      </surface>
    </collision>
    <visual name="cylinder">
      <pose>0 0 0.05 0 0 0</pose>
      <geometry>
        <cylinder>
          <length>0.1</length>
          <radius>0.01</radius>
        </cylinder>
      </geometry>
      <material>
  <ambient>0 0 0 1</ambient>
  <emissive>0 0 0 1</emissive>
  <diffuse>0 0 0 1</diffuse>
  <specular>1 1 1 1</specular>
</material>

    </visual>
    <collision name="sphere">
      <geometry>
        <sphere>
          <radius>0.01</radius>
        </sphere>
      </geometry>
      <surface>
        <contact>
          <ode>
            <kp>1e5</kp>
            <kd>1</kd>
            <max_vel>0.1</max_vel>
            <min_depth>0.0015</min_depth>
          </ode>
        </contact>
        <friction>
          <ode>
            <mu>1.0</mu>
            <mu2>1.0</mu2>
          </ode>
        </friction>
      </surface>
    </collision>

    <visual name="sphere">
      <geometry>
        <sphere>
          <radius>0.01</radius>
        </sphere>
      </geometry>
      <material>
  <ambient>0 0 0 1</ambient>
  <emissive>0 0 0 1</emissive>
  <diffuse>0 0 0 1</diffuse>
  <specular>1 1 1 1</specular>
</material>

    </visual>



  </link>

  <joint name="joint_9" type="universal">
    <child>link_9</child>
    <parent>link_8</parent>
    <axis>
      <xyz>0 1 0</xyz>
      <limit>
        <lower>-1.5707963267948966</lower>
        <upper>1.5707963267948966</upper>
      </limit>
    </axis>
    <axis2>
      <xyz>-1 0 0</xyz>
      <limit>
        <lower>-1.5707963267948966</lower>
        <upper>1.5707963267948966</upper>
      </limit>
    </axis2>
    <physics>
      <ode>
        <cfm_damping>1</cfm_damping>
      </ode>
    </physics>
  </joint>



  <link name="link_10">
    <pose>0.5290067270632258 0.08090169943749476 0 0 1.5707963267948966 -0.9424777960769379</pose>
    <inertial>
      <pose>0 0 0.05 0 0 0</pose>
      <mass>0.05</mass>
      <inertia>
        <ixx>0.0001</ixx>
        <iyy>0.0001</iyy>
        <izz>0.0001</izz>
      </inertia>
    </inertial>

    <collision name="cylinder">
      <pose>0 0 0.05 0 0 0</pose>
      <geometry>
        <cylinder>
          <length>0.1</length>
          <radius>0.01</radius>
        </cylinder>
      </geometry>
      <surface>
        <contact>
          <ode>
            <kp>1e5</kp>
            <kd>1</kd>
            <max_vel>0.1</max_vel>
            <min_depth>0.0015</min_depth>
          </ode>
        </contact>
        <friction>
          <ode>
            <mu>1.0</mu>
            <mu2>1.0</mu2>
          </ode>
        </friction>
      </surface>
    </collision>
    <visual name="cylinder">
      <pose>0 0 0.05 0 0 0</pose>
      <geometry>
        <cylinder>
          <length>0.1</length>
          <radius>0.01</radius>
        </cylinder>
      </geometry>
      <material>
  <ambient>0 0 0 1</ambient>
  <emissive>0 0 0 1</emissive>
  <diffuse>0 0 0 1</diffuse>
  <specular>1 1 1 1</specular>
</material>

    </visual>
    <collision name="sphere">
      <geometry>
        <sphere>
          <radius>0.01</radius>
        </sphere>
      </geometry>
      <surface>
        <contact>
          <ode>
            <kp>1e5</kp>
            <kd>1</kd>
            <max_vel>0.1</max_vel>
            <min_depth>0.0015</min_depth>
          </ode>
        </contact>
        <friction>
          <ode>
            <mu>1.0</mu>
            <mu2>1.0</mu2>
          </ode>
        </friction>
      </surface>
    </collision>

    <visual name="sphere">
      <geometry>
        <sphere>
          <radius>0.01</radius>
        </sphere>
      </geometry>
      <material>
  <ambient>0 0 0 1</ambient>
  <emissive>0 0 0 1</emissive>
  <diffuse>0 0 0 1</diffuse>
  <specular>1 1 1 1</specular>
</material>

    </visual>



  </link>

  <joint name="joint_10" type="universal">
    <child>link_10</child>
    <parent>link_9</parent>
    <axis>
      <xyz>0 1 0</xyz>
      <limit>
        <lower>-1.5707963267948966</lower>
        <upper>1.5707963267948966</upper>
      </limit>
    </axis>
    <axis2>
      <xyz>-1 0 0</xyz>
      <limit>
        <lower>-1.5707963267948966</lower>
        <upper>1.5707963267948966</upper>
      </limit>
    </axis2>
    <physics>
      <ode>
        <cfm_damping>1</cfm_damping>
      </ode>
    </physics>
  </joint>



  <link name="link_11">
    <pose>0.5877852522924731 0 0 0 1.5707963267948966 -0.9424777960769379</pose>
    <inertial>
      <pose>0 0 0.05 0 0 0</pose>
      <mass>0.05</mass>
      <inertia>
        <ixx>0.0001</ixx>
        <iyy>0.0001</iyy>
        <izz>0.0001</izz>
      </inertia>
    </inertial>

    <collision name="cylinder">
      <pose>0 0 0.05 0 0 0</pose>
      <geometry>
        <cylinder>
          <length>0.1</length>
          <radius>0.01</radius>
        </cylinder>
      </geometry>
      <surface>
        <contact>
          <ode>
            <kp>1e5</kp>
            <kd>1</kd>
            <max_vel>0.1</max_vel>
            <min_depth>0.0015</min_depth>
          </ode>
        </contact>
        <friction>
          <ode>
            <mu>1.0</mu>
            <mu2>1.0</mu2>
          </ode>
        </friction>
      </surface>
    </collision>
    <visual name="cylinder">
      <pose>0 0 0.05 0 0 0</pose>
      <geometry>
        <cylinder>
          <length>0.1</length>
          <radius>0.01</radius>
        </cylinder>
      </geometry>
      <material>
  <ambient>0 0 0 1</ambient>
  <emissive>0 0 0 1</emissive>
  <diffuse>0 0 0 1</diffuse>
  <specular>1 1 1 1</specular>
</material>

    </visual>
    <collision name="sphere">
      <geometry>
        <sphere>
          <radius>0.01</radius>
        </sphere>
      </geometry>
      <surface>
        <contact>
          <ode>
            <kp>1e5</kp>
            <kd>1</kd>
            <max_vel>0.1</max_vel>
            <min_depth>0.0015</min_depth>
          </ode>
        </contact>
        <friction>
          <ode>
            <mu>1.0</mu>
            <mu2>1.0</mu2>
          </ode>
        </friction>
      </surface>
    </collision>

    <visual name="sphere">
      <geometry>
        <sphere>
          <radius>0.01</radius>
        </sphere>
      </geometry>
      <material>
  <ambient>0 0 0 1</ambient>
  <emissive>0 0 0 1</emissive>
  <diffuse>0 0 0 1</diffuse>
  <specular>1 1 1 1</specular>
</material>

    </visual>



  </link>

  <joint name="joint_11" type="universal">
    <child>link_11</child>
    <parent>link_10</parent>
    <axis>
      <xyz>0 1 0</xyz>
      <limit>
        <lower>-1.5707963267948966</lower>
        <upper>1.5707963267948966</upper>
      </limit>
    </axis>
    <axis2>
      <xyz>-1 0 0</xyz>
      <limit>
        <lower>-1.5707963267948966</lower>
        <upper>1.5707963267948966</upper>
      </limit>
    </axis2>
    <physics>
      <ode>
        <cfm_damping>1</cfm_damping>
      </ode>
    </physics>
  </joint>



  <link name="link_12">
    <pose>0.6465637775217205 -0.08090169943749476 0 0 1.5707963267948966 0.9424777960769379</pose>
    <inertial>
      <pose>0 0 0.05 0 0 0</pose>
      <mass>0.05</mass>
      <inertia>
        <ixx>0.0001</ixx>
        <iyy>0.0001</iyy>
        <izz>0.0001</izz>
      </inertia>
    </inertial>

    <collision name="cylinder">
      <pose>0 0 0.05 0 0 0</pose>
      <geometry>
        <cylinder>
          <length>0.1</length>
          <radius>0.01</radius>
        </cylinder>
      </geometry>
      <surface>
        <contact>
          <ode>
            <kp>1e5</kp>
            <kd>1</kd>
            <max_vel>0.1</max_vel>
            <min_depth>0.0015</min_depth>
          </ode>
        </contact>
        <friction>
          <ode>
            <mu>1.0</mu>
            <mu2>1.0</mu2>
          </ode>
        </friction>
      </surface>
    </collision>
    <visual name="cylinder">
      <pose>0 0 0.05 0 0 0</pose>
      <geometry>
        <cylinder>
          <length>0.1</length>
          <radius>0.01</radius>
        </cylinder>
      </geometry>
      <material>
  <ambient>0 0 0 1</ambient>
  <emissive>0 0 0 1</emissive>
  <diffuse>0 0 0 1</diffuse>
  <specular>1 1 1 1</specular>
</material>

    </visual>
    <collision name="sphere">
      <geometry>
        <sphere>
          <radius>0.01</radius>
        </sphere>
      </geometry>
      <surface>
        <contact>
          <ode>
            <kp>1e5</kp>
            <kd>1</kd>
            <max_vel>0.1</max_vel>
            <min_depth>0.0015</min_depth>
          </ode>
        </contact>
        <friction>
          <ode>
            <mu>1.0</mu>
            <mu2>1.0</mu2>
          </ode>
        </friction>
      </surface>
    </collision>

    <visual name="sphere">
      <geometry>
        <sphere>
          <radius>0.01</radius>
        </sphere>
      </geometry>
      <material>
  <ambient>0 0 0 1</ambient>
  <emissive>0 0 0 1</emissive>
  <diffuse>0 0 0 1</diffuse>
  <specular>1 1 1 1</specular>
</material>

    </visual>



  </link>

  <joint name="joint_12" type="universal">
    <child>link_12</child>
    <parent>link_11</parent>
    <axis>
      <xyz>0 1 0</xyz>
      <limit>
        <lower>-1.5707963267948966</lower>
        <upper>1.5707963267948966</upper>
      </limit>
    </axis>
    <axis2>
      <xyz>-1 0 0</xyz>
      <limit>
        <lower>-1.5707963267948966</lower>
        <upper>1.5707963267948966</upper>
      </limit>
    </axis2>
    <physics>
      <ode>
        <cfm_damping>1</cfm_damping>
      </ode>
    </physics>
  </joint>



  <link name="link_13">
    <pose>0.7053423027509679 0 0 0 1.5707963267948966 0.9424777960769379</pose>
    <inertial>
      <pose>0 0 0.05 0 0 0</pose>
      <mass>0.05</mass>
      <inertia>
        <ixx>0.0001</ixx>
        <iyy>0.0001</iyy>
        <izz>0.0001</izz>
      </inertia>
    </inertial>

    <collision name="cylinder">
      <pose>0 0 0.05 0 0 0</pose>
      <geometry>
        <cylinder>
          <length>0.1</length>
          <radius>0.01</radius>
        </cylinder>
      </geometry>
      <surface>
        <contact>
          <ode>
            <kp>1e5</kp>
            <kd>1</kd>
            <max_vel>0.1</max_vel>
            <min_depth>0.0015</min_depth>
          </ode>
        </contact>
        <friction>
          <ode>
            <mu>1.0</mu>
            <mu2>1.0</mu2>
          </ode>
        </friction>
      </surface>
    </collision>
    <visual name="cylinder">
      <pose>0 0 0.05 0 0 0</pose>
      <geometry>
        <cylinder>
          <length>0.1</length>
          <radius>0.01</radius>
        </cylinder>
      </geometry>
      <material>
  <ambient>0 0 0 1</ambient>
  <emissive>0 0 0 1</emissive>
  <diffuse>0 0 0 1</diffuse>
  <specular>1 1 1 1</specular>
</material>

    </visual>
    <collision name="sphere">
      <geometry>
        <sphere>
          <radius>0.01</radius>
        </sphere>
      </geometry>
      <surface>
        <contact>
          <ode>
            <kp>1e5</kp>
            <kd>1</kd>
            <max_vel>0.1</max_vel>
            <min_depth>0.0015</min_depth>
          </ode>
        </contact>
        <friction>
          <ode>
            <mu>1.0</mu>
            <mu2>1.0</mu2>
          </ode>
        </friction>
      </surface>
    </collision>

    <visual name="sphere">
      <geometry>
        <sphere>
          <radius>0.01</radius>
        </sphere>
      </geometry>
      <material>
  <ambient>0 0 0 1</ambient>
  <emissive>0 0 0 1</emissive>
  <diffuse>0 0 0 1</diffuse>
  <specular>1 1 1 1</specular>
</material>

    </visual>



  </link>

  <joint name="joint_13" type="universal">
    <child>link_13</child>
    <parent>link_12</parent>
    <axis>
      <xyz>0 1 0</xyz>
      <limit>
        <lower>-1.5707963267948966</lower>
        <upper>1.5707963267948966</upper>
      </limit>
    </axis>
    <axis2>
      <xyz>-1 0 0</xyz>
      <limit>
        <lower>-1.5707963267948966</lower>
        <upper>1.5707963267948966</upper>
      </limit>
    </axis2>
    <physics>
      <ode>
        <cfm_damping>1</cfm_damping>
      </ode>
    </physics>
  </joint>



  <link name="link_14">
    <pose>0.7641208279802151 0.08090169943749476 0 0 1.5707963267948966 -0.9424777960769379</pose>
    <inertial>
      <pose>0 0 0.05 0 0 0</pose>
      <mass>0.05</mass>
      <inertia>
        <ixx>0.0001</ixx>
        <iyy>0.0001</iyy>
        <izz>0.0001</izz>
      </inertia>
    </inertial>

    <collision name="cylinder">
      <pose>0 0 0.05 0 0 0</pose>
      <geometry>
        <cylinder>
          <length>0.1</length>
          <radius>0.01</radius>
        </cylinder>
      </geometry>
      <surface>
        <contact>
          <ode>
            <kp>1e5</kp>
            <kd>1</kd>
            <max_vel>0.1</max_vel>
            <min_depth>0.0015</min_depth>
          </ode>
        </contact>
        <friction>
          <ode>
            <mu>1.0</mu>
            <mu2>1.0</mu2>
          </ode>
        </friction>
      </surface>
    </collision>
    <visual name="cylinder">
      <pose>0 0 0.05 0 0 0</pose>
      <geometry>
        <cylinder>
          <length>0.1</length>
          <radius>0.01</radius>
        </cylinder>
      </geometry>
      <material>
  <ambient>0 0 0 1</ambient>
  <emissive>0 0 0 1</emissive>
  <diffuse>0 0 0 1</diffuse>
  <specular>1 1 1 1</specular>
</material>

    </visual>
    <collision name="sphere">
      <geometry>
        <sphere>
          <radius>0.01</radius>
        </sphere>
      </geometry>
      <surface>
        <contact>
          <ode>
            <kp>1e5</kp>
            <kd>1</kd>
            <max_vel>0.1</max_vel>
            <min_depth>0.0015</min_depth>
          </ode>
        </contact>
        <friction>
          <ode>
            <mu>1.0</mu>
            <mu2>1.0</mu2>
          </ode>
        </friction>
      </surface>
    </collision>

    <visual name="sphere">
      <geometry>
        <sphere>
          <radius>0.01</radius>
        </sphere>
      </geometry>
      <material>
  <ambient>0 0 0 1</ambient>
  <emissive>0 0 0 1</emissive>
  <diffuse>0 0 0 1</diffuse>
  <specular>1 1 1 1</specular>
</material>

    </visual>



  </link>

  <joint name="joint_14" type="universal">
    <child>link_14</child>
    <parent>link_13</parent>
    <axis>
      <xyz>0 1 0</xyz>
      <limit>
        <lower>-1.5707963267948966</lower>
        <upper>1.5707963267948966</upper>
      </limit>
    </axis>
    <axis2>
      <xyz>-1 0 0</xyz>
      <limit>
        <lower>-1.5707963267948966</lower>
        <upper>1.5707963267948966</upper>
      </limit>
    </axis2>
    <physics>
      <ode>
        <cfm_damping>1</cfm_damping>
      </ode>
    </physics>
  </joint>



  <link name="link_15">
    <pose>0.8228993532094625 0 0 0 1.5707963267948966 -0.9424777960769379</pose>
    <inertial>
      <pose>0 0 0.05 0 0 0</pose>
      <mass>0.05</mass>
      <inertia>
        <ixx>0.0001</ixx>
        <iyy>0.0001</iyy>
        <izz>0.0001</izz>
      </inertia>
    </inertial>

    <collision name="cylinder">
      <pose>0 0 0.05 0 0 0</pose>
      <geometry>
        <cylinder>
          <length>0.1</length>
          <radius>0.01</radius>
        </cylinder>
      </geometry>
      <surface>
        <contact>
          <ode>
            <kp>1e5</kp>
            <kd>1</kd>
            <max_vel>0.1</max_vel>
            <min_depth>0.0015</min_depth>
          </ode>
        </contact>
        <friction>
          <ode>
            <mu>1.0</mu>
            <mu2>1.0</mu2>
          </ode>
        </friction>
      </surface>
    </collision>
    <visual name="cylinder">
      <pose>0 0 0.05 0 0 0</pose>
      <geometry>
        <cylinder>
          <length>0.1</length>
          <radius>0.01</radius>
        </cylinder>
      </geometry>
      <material>
  <ambient>0 0 0 1</ambient>
  <emissive>0 0 0 1</emissive>
  <diffuse>0 0 0 1</diffuse>
  <specular>1 1 1 1</specular>
</material>

    </visual>
    <collision name="sphere">
      <geometry>
        <sphere>
          <radius>0.01</radius>
        </sphere>
      </geometry>
      <surface>
        <contact>
          <ode>
            <kp>1e5</kp>
            <kd>1</kd>
            <max_vel>0.1</max_vel>
            <min_depth>0.0015</min_depth>
          </ode>
        </contact>
        <friction>
          <ode>
            <mu>1.0</mu>
            <mu2>1.0</mu2>
          </ode>
        </friction>
      </surface>
    </collision>

    <visual name="sphere">
      <geometry>
        <sphere>
          <radius>0.01</radius>
        </sphere>
      </geometry>
      <material>
  <ambient>0 0 0 1</ambient>
  <emissive>0 0 0 1</emissive>
  <diffuse>0 0 0 1</diffuse>
  <specular>1 1 1 1</specular>
</material>

    </visual>



  </link>

  <joint name="joint_15" type="universal">
    <child>link_15</child>
    <parent>link_14</parent>
    <axis>
      <xyz>0 1 0</xyz>
      <limit>
        <lower>-1.5707963267948966</lower>
        <upper>1.5707963267948966</upper>
      </limit>
    </axis>
    <axis2>
      <xyz>-1 0 0</xyz>
      <limit>
        <lower>-1.5707963267948966</lower>
        <upper>1.5707963267948966</upper>
      </limit>
    </axis2>
    <physics>
      <ode>
        <cfm_damping>1</cfm_damping>
      </ode>
    </physics>
  </joint>



  <link name="link_16">
    <pose>0.8816778784387097 -0.08090169943749476 0 0 1.5707963267948966 0.9424777960769379</pose>
    <inertial>
      <pose>0 0 0.05 0 0 0</pose>
      <mass>0.05</mass>
      <inertia>
        <ixx>0.0001</ixx>
        <iyy>0.0001</iyy>
        <izz>0.0001</izz>
      </inertia>
    </inertial>

    <collision name="cylinder">
      <pose>0 0 0.09000000000000001 0 0 0</pose>
      <geometry>
        <cylinder>
          <length>0.18000000000000002</length>
          <radius>0.013999999999999999</radius>
        </cylinder>
      </geometry>
      <surface>
        <contact>
          <ode>
            <kp>1e5</kp>
            <kd>1</kd>
            <max_vel>0.1</max_vel>
            <min_depth>0.0015</min_depth>
          </ode>
        </contact>
        <friction>
          <ode>
            <mu>1.0</mu>
            <mu2>1.0</mu2>
          </ode>
        </friction>
      </surface>
    </collision>
    <visual name="cylinder">
      <pose>0 0 0.09000000000000001 0 0 0</pose>
      <geometry>
        <cylinder>
          <length>0.18000000000000002</length>
          <radius>0.013999999999999999</radius>
        </cylinder>
      </geometry>
      <material>
  <ambient>0 0 0.3 1</ambient>
  <emissive>0 0 0 1</emissive>
  <diffuse>0 0 0.1 1</diffuse>
  <specular>1 1 1 1</specular>
</material>

    </visual>
    <collision name="sphere">
      <geometry>
        <sphere>
          <radius>0.013999999999999999</radius>
        </sphere>
      </geometry>
      <surface>
        <contact>
          <ode>
            <kp>1e5</kp>
            <kd>1</kd>
            <max_vel>0.1</max_vel>
            <min_depth>0.0015</min_depth>
          </ode>
        </contact>
        <friction>
          <ode>
            <mu>1.0</mu>
            <mu2>1.0</mu2>
          </ode>
        </friction>
      </surface>
    </collision>

    <visual name="sphere">
      <geometry>
        <sphere>
          <radius>0.013999999999999999</radius>
        </sphere>
      </geometry>
      <material>
  <ambient>0 0 0.3 1</ambient>
  <emissive>0 0 0 1</emissive>
  <diffuse>0 0 0.1 1</diffuse>
  <specular>1 1 1 1</specular>
</material>

    </visual>


    <collision name="plug_outer_1">
      <pose>0 0 0.16200000000000003 0 0 0</pose>
      <geometry>
        <cylinder>
          <length>0.010000000000000002</length>
          <radius>0.025</radius>
        </cylinder>
      </geometry>
      <surface>
        <contact>
          <ode>
            <kp>1e5</kp>
            <kd>1</kd>
            <max_vel>0.1</max_vel>
            <min_depth>0.0015</min_depth>
          </ode>
        </contact>
        <friction>
          <ode>
            <mu>1.0</mu>
            <mu2>1.0</mu2>
          </ode>
        </friction>
      </surface>
    </collision>

    <visual name="plug_outer_1">
      <pose>0 0 0.16200000000000003 0 0 0</pose>
      <geometry>
        <cylinder>
          <length>0.010000000000000002</length>
          <radius>0.025</radius>
        </cylinder>
      </geometry>
      <material>
  <ambient>0 0 0.3 1</ambient>
  <emissive>0 0 0.5 1</emissive>
  <diffuse>0 0 0.1 1</diffuse>
  <specular>1 1 1 1</specular>
</material>

    </visual>

    <collision name="plug_middle_1">
      <pose>0 0 0.16200000000000003 0 0 0</pose>
      <geometry>
        <cylinder>
          <length>0.020000000000000004</length>
          <radius>0.017</radius>
        </cylinder>
      </geometry>
      <surface>
        <contact>
          <ode>
            <kp>1e5</kp>
            <kd>1</kd>
            <max_vel>0.1</max_vel>
            <min_depth>0.0015</min_depth>
          </ode>
        </contact>
        <friction>
          <ode>
            <mu>1.0</mu>
            <mu2>1.0</mu2>
          </ode>
        </friction>
      </surface>
    </collision>

    <visual name="plug_middle_1">
      <pose>0 0 0.16200000000000003 0 0 0</pose>
      <geometry>
        <cylinder>
          <length>0.020000000000000004</length>
          <radius>0.017</radius>
        </cylinder>
      </geometry>
      <material>
  <ambient>0 0 0.7 1</ambient>
  <emissive>0 0 0 1</emissive>
  <diffuse>0 0 0.1 1</diffuse>
  <specular>1 1 1 1</specular>
</material>

    </visual>

    <collision name="plug_outer_2">
      <pose>0 0 0.018000000000000002 0 0 0</pose>
      <geometry>
        <cylinder>
          <length>0.010000000000000002</length>
          <radius>0.025</radius>
        </cylinder>
      </geometry>
      <surface>
        <contact>
          <ode>
            <kp>1e5</kp>
            <kd>1</kd>
            <max_vel>0.1</max_vel>
            <min_depth>0.0015</min_depth>
          </ode>
        </contact>
        <friction>
          <ode>
            <mu>1.0</mu>
            <mu2>1.0</mu2>
          </ode>
        </friction>
      </surface>
    </collision>

    <visual name="plug_outer_2">
      <pose>0 0 0.018000000000000002 0 0 0</pose>
      <geometry>
        <cylinder>
          <length>0.010000000000000002</length>
          <radius>0.025</radius>
        </cylinder>
      </geometry>
      <material>
  <ambient>0 0 0.3 1</ambient>
  <emissive>0 0 0.5 1</emissive>
  <diffuse>0 0 0.1 1</diffuse>
  <specular>1 1 1 1</specular>
</material>

    </visual>

    <collision name="plug_middle_2">
      <pose>0 0 0.018000000000000002 0 0 0</pose>
      <geometry>
        <cylinder>
          <length>0.020000000000000004</length>
          <radius>0.017</radius>
        </cylinder>
      </geometry>
      <surface>
        <contact>
          <ode>
            <kp>1e5</kp>
            <kd>1</kd>
            <max_vel>0.1</max_vel>
            <min_depth>0.0015</min_depth>
          </ode>
        </contact>
        <friction>
          <ode>
            <mu>1.0</mu>
            <mu2>1.0</mu2>
          </ode>
        </friction>
      </surface>
    </collision>

    <visual name="plug_middle_2">
      <pose>0 0 0.018000000000000002 0 0 0</pose>
      <geometry>
        <cylinder>
          <length>0.020000000000000004</length>
          <radius>0.017</radius>
        </cylinder>
      </geometry>
      <material>
  <ambient>0 0 0.7 1</ambient>
  <emissive>0 0 0 1</emissive>
  <diffuse>0 0 0.1 1</diffuse>
  <specular>1 1 1 1</specular>
</material>

    </visual>

    <sensor name="tip_sensor" type="contact">
      <contact>
        <collision>plug_outer_1</collision>
        <collision>plug_outer_2</collision>
        <collision>plug_middle_1</collision>
        <collision>plug_middle_2</collision>
        <collision>cylinder</collision>
        <collision>sphere</collision>
      </contact>
    </sensor>



  </link>

  <joint name="joint_16" type="universal">
    <child>link_16</child>
    <parent>link_15</parent>
    <axis>
      <xyz>0 1 0</xyz>
      <limit>
        <lower>-1.5707963267948966</lower>
        <upper>1.5707963267948966</upper>
      </limit>
    </axis>
    <axis2>
      <xyz>-1 0 0</xyz>
      <limit>
        <lower>-1.5707963267948966</lower>
        <upper>1.5707963267948966</upper>
      </limit>
    </axis2>
    <physics>
      <ode>
        <cfm_damping>1</cfm_damping>
      </ode>
    </physics>
  </joint>



  <joint name="world" type="fixed">
    <child>link_0</child>
    <parent>world</parent>
  </joint>

  <plugin name="touch_valkyrie_cable" filename="libTouchPlugin.so">
    <sensor>tip_sensor</sensor>
    <target>valkyrie</target>
    <time>0.5</time>
    <namespace>task2/checkpoint4</namespace>
  </plugin>

</model>


    <!-- Checkpoint 2 - Box plugin -->


    <plugin name="boxT2CP2" filename="libBoxContainsPlugin.so">
      <entity>solar_panel</entity>
      <namespace>task2/checkpoint2</namespace>
      <pose>
        7.914113172079968
        10.442487286514524
        1.1
        0
        0
        0.7853981633974481
      </pose>
      <size>1.47 0.95 0.45</size>
    </plugin>

    <!-- Bling -->
    <include>
      <name>bling_10</name>
      <pose>
      9.73420602685414
      8.622394431740352
      0
      0
      0
      -2.3561944901923453
      </pose>
      <uri>model://mars_rock_2</uri>
    </include>


    <!-- Walkway -->
    <include>
      <name>walkway_10</name>
      <pose>
      9.380652636260868
      10.053578556861924
      -0.052151
      0
      0
      -0.7853981633974485
      </pose>
      <uri>model://walkway_metal_straight</uri>
    </include>


    <!-- Bling -->
    <include>
      <name>bling_11</name>
      <pose>
      11.023968795738405
      9.487893131912685
      0
      0
      0
      -1.570796326794897
      </pose>
      <uri>model://mars_crate_long</uri>
    </include>


    <!-- Bling -->
    <include>
      <name>bling_12</name>
      <pose>
      9.097809923786249
      11.41405200386484
      0
      0
      0
      0.7853981633974481
      </pose>
      <uri>model://mars_crate</uri>
    </include>


    <!-- Final Box 2 -->
    <include>
      <name>walkway_11</name>
      <pose>
      11.535914105317465
      12.208840025918521
      -0.052151
      0
      0
      -2.3561944901923453
      </pose>
      <uri>model://walkway_finish_adjacent</uri>
    </include>


    <!-- Checkpoint 6 - Box plugin -->
    <plugin name="boxT2CP6" filename="libBoxContainsPlugin.so">
      <entity>valkyrie</entity>
      <namespace>task2/checkpoint6</namespace>
      <pose>
        11.535914105317465
        12.208840025918521
        2.5
        0
        0
        -2.3561944901923453
      </pose>
      <size>3.048 3.048 5.0</size>
    </plugin>

    <!-- Bling -->
    <include>
      <name>bling_13</name>
      <pose>
      10.104729980195893
      13.640024151040093
      0
      0
      0
      0.785398163397448
      </pose>
      <uri>model://mars_rock_2</uri>
    </include>


    <!-- Bling -->
    <include>
      <name>bling_14</name>
      <pose>
      13.179230264795002
      13.852156185396058
      0
      0
      0
      -2.7755575615628914e-16
      </pose>
      <uri>model://mars_crate_long</uri>
    </include>




    <!-- /TASK 2 -->




    <!-- TASK 3 -->



    <!-- Task 3 start - Box plugin -->


    <plugin name="boxT3Start" filename="libBoxContainsPlugin.so">
      <entity>valkyrie</entity>
      <namespace>task3/start</namespace>
      <pose>
        12.967098230439037
        10.77765590079695
        2.5
        0
        0
        -2.3561944901923453
      </pose>
      <size>1.524 1 5.0</size>
    </plugin>

    <!-- Walkway -->
    <include>
      <name>walkway_12</name>
      <pose>
      12.613544839845764
      11.131209291390222
      -0.052151
      0
      0
      -2.3561944901923453
      </pose>
      <uri>model://walkway_metal_straight</uri>
    </include>


    <!-- Walkway -->
    <include>
      <name>walkway_13</name>
      <pose>
      14.768806308902361
      10.053578556861924
      -0.052151
      0
      0
      2.356194490192345
      </pose>
      <uri>model://walkway_metal_90</uri>
    </include>


    <!-- Habitat -->




<!-- Base model - static frame -->

<model name="habitat_base">
  <static>true</static>

  <pose>
  23.53693039561555
  9.346471775675372
  0
  0
  0
  -0.7853981633974487
  </pose>

  <link name="base">

    <!-- Stairs collisions -->



    <collision name="step_0">
      <pose>-6.686 -5.597 0.1079 0 0 0</pose>
      <geometry>
        <box>
          <size>2.46997 0.317063 0.21 </size>
        </box>
      </geometry>
    </collision>



    <collision name="step_1">
      <pose>-6.686 -5.3581 0.311 0 0 0</pose>
      <geometry>
        <box>
          <size>2.46997 0.317063 0.21 </size>
        </box>
      </geometry>
    </collision>



    <collision name="step_2">
      <pose>-6.686 -5.1192 0.5141 0 0 0</pose>
      <geometry>
        <box>
          <size>2.46997 0.317063 0.21 </size>
        </box>
      </geometry>
    </collision>



    <collision name="step_3">
      <pose>-6.686 -4.8803 0.7172 0 0 0</pose>
      <geometry>
        <box>
          <size>2.46997 0.317063 0.21 </size>
        </box>
      </geometry>
    </collision>



    <collision name="step_4">
      <pose>-6.686 -4.641400000000001 0.9203 0 0 0</pose>
      <geometry>
        <box>
          <size>2.46997 0.317063 0.21 </size>
        </box>
      </geometry>
    </collision>



    <collision name="step_5">
      <pose>-6.686 -4.4025 1.1234000000000002 0 0 0</pose>
      <geometry>
        <box>
          <size>2.46997 0.317063 0.21 </size>
        </box>
      </geometry>
    </collision>



    <collision name="step_6">
      <pose>-6.686 -4.163600000000001 1.3264999999999998 0 0 0</pose>
      <geometry>
        <box>
          <size>2.46997 0.317063 0.21 </size>
        </box>
      </geometry>
    </collision>



    <collision name="step_7">
      <pose>-6.686 -3.9247000000000005 1.5295999999999998 0 0 0</pose>
      <geometry>
        <box>
          <size>2.46997 0.317063 0.21 </size>
        </box>
      </geometry>
    </collision>



    <!-- floor collisions -->



    <collision name="floor_1">
      <pose>2.0 0.155 1.71 0 0 0</pose>
      <geometry>
        <box>
          <size>20.0 8.0 0.21 </size>
        </box>
      </geometry>
    </collision>



    <collision name="floor_2">
      <pose>0.0 0.155 1.71 0 0 0</pose>
      <geometry>
        <box>
          <size>8.0 12.0 0.21 </size>
        </box>
      </geometry>
    </collision>

    <!-- Rail collisions -->



    <collision name="rail_1_left">
      <pose>-7.92 -4.838 1.828 0 -0.7133 1.5707963267948966</pose>
      <geometry>
        <box>
          <size>2.46 0.055 0.034 </size>
        </box>
      </geometry>
    </collision>



    <collision name="rail_1_right">
      <pose>-5.4505 -4.838 1.828 0 -0.7133 1.5707963267948966</pose>
      <geometry>
        <box>
          <size>2.46 0.055 0.034 </size>
        </box>
      </geometry>
    </collision>



    <collision name="rail_2_left">
      <pose>-7.92 -4.678 1.368 0 -0.709 1.5707963267948966</pose>
      <geometry>
        <box>
          <size>2.52 0.055 0.037 </size>
        </box>
      </geometry>
    </collision>



    <collision name="rail_2_right">
      <pose>-5.4505 -4.678 1.368 0 -0.709 1.5707963267948966</pose>
      <geometry>
        <box>
          <size>2.52 0.055 0.037 </size>
        </box>
      </geometry>
    </collision>



    <collision name="rail_3_left">
      <pose>-7.92 -2.13 2.625 0 0 1.5707963267948966</pose>
      <geometry>
        <box>
          <size>1.96 0.055 0.048 </size>
        </box>
      </geometry>
    </collision>



    <collision name="rail_3_right">
      <pose>-5.4305 -2.13 2.625 0 0 1.5707963267948966</pose>
      <geometry>
        <box>
          <size>1.96 0.055 0.048 </size>
        </box>
      </geometry>
    </collision>



    <collision name="rail_4_left">
      <pose>-7.92 -2.13 2.153 0 0 1.5707963267948966</pose>
      <geometry>
        <box>
          <size>1.96 0.055 0.048 </size>
        </box>
      </geometry>
    </collision>



    <collision name="rail_4_right">
      <pose>-5.4305 -2.13 2.153 0 0 1.5707963267948966</pose>
      <geometry>
        <box>
          <size>1.96 0.055 0.048 </size>
        </box>
      </geometry>
    </collision>



    <collision name="rail_5_left">
      <pose>-7.92 -3.64 2.153 0 0 1.5707963267948966</pose>
      <geometry>
        <box>
          <size>0.16 0.055 0.048 </size>
        </box>
      </geometry>
    </collision>



    <collision name="rail_5_right">
      <pose>-5.4505 -3.64 2.153 0 0 1.5707963267948966</pose>
      <geometry>
        <box>
          <size>0.16 0.055 0.048 </size>
        </box>
      </geometry>
    </collision>



    <collision name="rail_6_left">
      <pose>-7.92 -3.735 2.625 0 0 1.5707963267948966</pose>
      <geometry>
        <box>
          <size>0.37 0.055 0.048 </size>
        </box>
      </geometry>
    </collision>



    <collision name="rail_6_right">
      <pose>-5.4505 -3.735 2.625 0 0 1.5707963267948966</pose>
      <geometry>
        <box>
          <size>0.37 0.055 0.048 </size>
        </box>
      </geometry>
    </collision>



    <collision name="rail_7_left">
      <pose>-7.92 -5.88 0.555 0 0 1.5707963267948966</pose>
      <geometry>
        <box>
          <size>0.46 0.055 0.048 </size>
        </box>
      </geometry>
    </collision>



    <collision name="rail_7_right">
      <pose>-5.4505 -5.88 0.555 0 0 1.5707963267948966</pose>
      <geometry>
        <box>
          <size>0.46 0.055 0.048 </size>
        </box>
      </geometry>
    </collision>



    <collision name="rail_8_left">
      <pose>-7.92 -5.935 1.027 0 0 1.5707963267948966</pose>
      <geometry>
        <box>
          <size>0.35 0.055 0.048 </size>
        </box>
      </geometry>
    </collision>



    <collision name="rail_8_right">
      <pose>-5.4505 -5.935 1.027 0 0 1.5707963267948966</pose>
      <geometry>
        <box>
          <size>0.35 0.055 0.048 </size>
        </box>
      </geometry>
    </collision>



    <collision name="rail_9_left">
      <pose>-7.92 -5.65 0.335 0 0 1.5707963267948966</pose>
      <geometry>
        <box>
          <size>0.05 0.055 0.478 </size>
        </box>
      </geometry>
    </collision>



    <collision name="rail_9_right">
      <pose>-5.4505 -5.65 0.335 0 0 1.5707963267948966</pose>
      <geometry>
        <box>
          <size>0.05 0.055 0.478 </size>
        </box>
      </geometry>
    </collision>



    <collision name="rail_10_left">
      <pose>-7.92 -5.722 0.795 0 -0.325 1.5707963267948966</pose>
      <geometry>
        <box>
          <size>0.046 0.055 0.478 </size>
        </box>
      </geometry>
    </collision>



    <collision name="rail_10_right">
      <pose>-5.4505 -5.722 0.795 0 -0.325 1.5707963267948966</pose>
      <geometry>
        <box>
          <size>0.046 0.055 0.478 </size>
        </box>
      </geometry>
    </collision>



    <collision name="rail_11_left">
      <pose>-7.92 -3.738 1.89 0 0 1.5707963267948966</pose>
      <geometry>
        <box>
          <size>0.05 0.055 0.568 </size>
        </box>
      </geometry>
    </collision>



    <collision name="rail_11_right">
      <pose>-5.4505 -3.738 1.89 0 0 1.5707963267948966</pose>
      <geometry>
        <box>
          <size>0.05 0.055 0.568 </size>
        </box>
      </geometry>
    </collision>



    <collision name="rail_12_left">
      <pose>-7.92 -3.81 2.39 0 -0.325 1.5707963267948966</pose>
      <geometry>
        <box>
          <size>0.046 0.055 0.478 </size>
        </box>
      </geometry>
    </collision>



    <collision name="rail_12_right">
      <pose>-5.4505 -3.81 2.39 0 -0.325 1.5707963267948966</pose>
      <geometry>
        <box>
          <size>0.046 0.055 0.478 </size>
        </box>
      </geometry>
    </collision>



    <collision name="rail_13_left">
      <pose>-7.92 -2.842 2.12 0 0 1.5707963267948966</pose>
      <geometry>
        <box>
          <size>0.046 0.055 1.028 </size>
        </box>
      </geometry>
    </collision>



    <collision name="rail_13_right">
      <pose>-5.4305 -2.842 2.12 0 0 1.5707963267948966</pose>
      <geometry>
        <box>
          <size>0.046 0.055 1.028 </size>
        </box>
      </geometry>
    </collision>



    <collision name="rail_14_left">
      <pose>-7.92 -1.595 2.12 0 0 1.5707963267948966</pose>
      <geometry>
        <box>
          <size>0.046 0.055 1.028 </size>
        </box>
      </geometry>
    </collision>



    <collision name="rail_14_right">
      <pose>-5.4305 -1.595 2.12 0 0 1.5707963267948966</pose>
      <geometry>
        <box>
          <size>0.046 0.055 1.028 </size>
        </box>
      </geometry>
    </collision>



    <collision name="rail_15_left">
      <pose>-7.92 -6.15 0.568 0 0.29 1.5707963267948966</pose>
      <geometry>
        <box>
          <size>0.1 0.055 0.048 </size>
        </box>
      </geometry>
    </collision>



    <collision name="rail_15_right">
      <pose>-5.4505 -6.15 0.568 0 0.29 1.5707963267948966</pose>
      <geometry>
        <box>
          <size>0.1 0.055 0.048 </size>
        </box>
      </geometry>
    </collision>



    <collision name="rail_16_left">
      <pose>-7.92 -6.224 0.612 0 0.78 1.5707963267948966</pose>
      <geometry>
        <box>
          <size>0.11 0.055 0.046 </size>
        </box>
      </geometry>
    </collision>



    <collision name="rail_16_right">
      <pose>-5.4505 -6.224 0.612 0 0.78 1.5707963267948966</pose>
      <geometry>
        <box>
          <size>0.11 0.055 0.046 </size>
        </box>
      </geometry>
    </collision>



    <collision name="rail_17_left">
      <pose>-7.92 -6.271 0.691 0 1.3 1.5707963267948966</pose>
      <geometry>
        <box>
          <size>0.1 0.055 0.047 </size>
        </box>
      </geometry>
    </collision>



    <collision name="rail_17_right">
      <pose>-5.4505 -6.271 0.691 0 1.3 1.5707963267948966</pose>
      <geometry>
        <box>
          <size>0.1 0.055 0.047 </size>
        </box>
      </geometry>
    </collision>



    <collision name="rail_18_left">
      <pose>-7.92 -6.283 0.791 0 1.5707963267948966 1.5707963267948966</pose>
      <geometry>
        <box>
          <size>0.12 0.055 0.05 </size>
        </box>
      </geometry>
    </collision>



    <collision name="rail_18_right">
      <pose>-5.4505 -6.283 0.791 0 1.5707963267948966 1.5707963267948966</pose>
      <geometry>
        <box>
          <size>0.12 0.055 0.05 </size>
        </box>
      </geometry>
    </collision>



    <collision name="rail_19_left">
      <pose>-7.92 -6.271 0.891 0 1.86 1.5707963267948966</pose>
      <geometry>
        <box>
          <size>0.1 0.055 0.048 </size>
        </box>
      </geometry>
    </collision>



    <collision name="rail_19_right">
      <pose>-5.4505 -6.271 0.891 0 1.86 1.5707963267948966</pose>
      <geometry>
        <box>
          <size>0.1 0.055 0.048 </size>
        </box>
      </geometry>
    </collision>



    <collision name="rail_20_left">
      <pose>-7.92 -6.225 0.968 0 2.36 1.5707963267948966</pose>
      <geometry>
        <box>
          <size>0.107 0.055 0.048 </size>
        </box>
      </geometry>
    </collision>



    <collision name="rail_20_right">
      <pose>-5.4505 -6.225 0.968 0 2.36 1.5707963267948966</pose>
      <geometry>
        <box>
          <size>0.107 0.055 0.048 </size>
        </box>
      </geometry>
    </collision>



    <collision name="rail_21_left">
      <pose>-7.92 -6.15 1.014 0 -0.29 1.5707963267948966</pose>
      <geometry>
        <box>
          <size>0.1 0.055 0.048 </size>
        </box>
      </geometry>
    </collision>



    <collision name="rail_21_right">
      <pose>-5.4505 -6.15 1.014 0 -0.29 1.5707963267948966</pose>
      <geometry>
        <box>
          <size>0.1 0.055 0.048 </size>
        </box>
      </geometry>
    </collision>



    <collision name="rail_22_left">
      <pose>-7.92 -3.152 2.166 0 0.29 1.5707963267948966</pose>
      <geometry>
        <box>
          <size>0.1 0.055 0.048 </size>
        </box>
      </geometry>
    </collision>



    <collision name="rail_22_right">
      <pose>-5.4305 -3.152 2.166 0 0.29 1.5707963267948966</pose>
      <geometry>
        <box>
          <size>0.1 0.055 0.048 </size>
        </box>
      </geometry>
    </collision>



    <collision name="rail_23_left">
      <pose>-7.92 -3.226 2.21 0 0.78 1.5707963267948966</pose>
      <geometry>
        <box>
          <size>0.11 0.055 0.046 </size>
        </box>
      </geometry>
    </collision>



    <collision name="rail_23_right">
      <pose>-5.4305 -3.226 2.21 0 0.78 1.5707963267948966</pose>
      <geometry>
        <box>
          <size>0.11 0.055 0.046 </size>
        </box>
      </geometry>
    </collision>



    <collision name="rail_24_left">
      <pose>-7.92 -3.2729999999999997 2.289 0 1.3 1.5707963267948966</pose>
      <geometry>
        <box>
          <size>0.1 0.055 0.047 </size>
        </box>
      </geometry>
    </collision>



    <collision name="rail_24_right">
      <pose>-5.4305 -3.2729999999999997 2.289 0 1.3 1.5707963267948966</pose>
      <geometry>
        <box>
          <size>0.1 0.055 0.047 </size>
        </box>
      </geometry>
    </collision>



    <collision name="rail_25_left">
      <pose>-7.92 -3.285 2.3890000000000002 0 1.5707963267948966 1.5707963267948966</pose>
      <geometry>
        <box>
          <size>0.12 0.055 0.05 </size>
        </box>
      </geometry>
    </collision>



    <collision name="rail_25_right">
      <pose>-5.4305 -3.285 2.3890000000000002 0 1.5707963267948966 1.5707963267948966</pose>
      <geometry>
        <box>
          <size>0.12 0.055 0.05 </size>
        </box>
      </geometry>
    </collision>



    <collision name="rail_26_left">
      <pose>-7.92 -3.2729999999999997 2.489 0 1.86 1.5707963267948966</pose>
      <geometry>
        <box>
          <size>0.1 0.055 0.048 </size>
        </box>
      </geometry>
    </collision>



    <collision name="rail_26_right">
      <pose>-5.4305 -3.2729999999999997 2.489 0 1.86 1.5707963267948966</pose>
      <geometry>
        <box>
          <size>0.1 0.055 0.048 </size>
        </box>
      </geometry>
    </collision>



    <collision name="rail_27_left">
      <pose>-7.92 -3.2269999999999994 2.566 0 2.36 1.5707963267948966</pose>
      <geometry>
        <box>
          <size>0.107 0.055 0.048 </size>
        </box>
      </geometry>
    </collision>



    <collision name="rail_27_right">
      <pose>-5.4305 -3.2269999999999994 2.566 0 2.36 1.5707963267948966</pose>
      <geometry>
        <box>
          <size>0.107 0.055 0.048 </size>
        </box>
      </geometry>
    </collision>



    <collision name="rail_28_left">
      <pose>-7.92 -3.152 2.612 0 -0.29 1.5707963267948966</pose>
      <geometry>
        <box>
          <size>0.1 0.055 0.048 </size>
        </box>
      </geometry>
    </collision>



    <collision name="rail_28_right">
      <pose>-5.4305 -3.152 2.612 0 -0.29 1.5707963267948966</pose>
      <geometry>
        <box>
          <size>0.1 0.055 0.048 </size>
        </box>
      </geometry>
    </collision>



    <collision name="rail_29_left">
      <pose>-7.92 -3.515 2.166 0 -0.29 1.5707963267948966</pose>
      <geometry>
        <box>
          <size>0.1 0.055 0.048 </size>
        </box>
      </geometry>
    </collision>



    <collision name="rail_29_right">
      <pose>-5.4505 -3.515 2.166 0 -0.29 1.5707963267948966</pose>
      <geometry>
        <box>
          <size>0.1 0.055 0.048 </size>
        </box>
      </geometry>
    </collision>



    <collision name="rail_30_left">
      <pose>-7.92 -3.444 2.21 0 -0.78 1.5707963267948966</pose>
      <geometry>
        <box>
          <size>0.11 0.055 0.046 </size>
        </box>
      </geometry>
    </collision>



    <collision name="rail_30_right">
      <pose>-5.4505 -3.444 2.21 0 -0.78 1.5707963267948966</pose>
      <geometry>
        <box>
          <size>0.11 0.055 0.046 </size>
        </box>
      </geometry>
    </collision>



    <collision name="rail_31_left">
      <pose>-7.92 -3.397 2.289 0 -1.3 1.5707963267948966</pose>
      <geometry>
        <box>
          <size>0.1 0.055 0.047 </size>
        </box>
      </geometry>
    </collision>



    <collision name="rail_31_right">
      <pose>-5.4505 -3.397 2.289 0 -1.3 1.5707963267948966</pose>
      <geometry>
        <box>
          <size>0.1 0.055 0.047 </size>
        </box>
      </geometry>
    </collision>



    <collision name="rail_32_left">
      <pose>-7.92 -3.384 2.3890000000000002 0 -1.5707963267948966 1.5707963267948966</pose>
      <geometry>
        <box>
          <size>0.12 0.055 0.05 </size>
        </box>
      </geometry>
    </collision>



    <collision name="rail_32_right">
      <pose>-5.4505 -3.384 2.3890000000000002 0 -1.5707963267948966 1.5707963267948966</pose>
      <geometry>
        <box>
          <size>0.12 0.055 0.05 </size>
        </box>
      </geometry>
    </collision>



    <collision name="rail_33_left">
      <pose>-7.92 -3.396 2.489 0 -1.86 1.5707963267948966</pose>
      <geometry>
        <box>
          <size>0.1 0.055 0.048 </size>
        </box>
      </geometry>
    </collision>



    <collision name="rail_33_right">
      <pose>-5.4505 -3.396 2.489 0 -1.86 1.5707963267948966</pose>
      <geometry>
        <box>
          <size>0.1 0.055 0.048 </size>
        </box>
      </geometry>
    </collision>



    <collision name="rail_34_left">
      <pose>-7.92 -3.442 2.566 0 -2.36 1.5707963267948966</pose>
      <geometry>
        <box>
          <size>0.107 0.055 0.048 </size>
        </box>
      </geometry>
    </collision>



    <collision name="rail_34_right">
      <pose>-5.4505 -3.442 2.566 0 -2.36 1.5707963267948966</pose>
      <geometry>
        <box>
          <size>0.107 0.055 0.048 </size>
        </box>
      </geometry>
    </collision>



    <collision name="rail_35_left">
      <pose>-7.92 -3.52 2.612 0 0.29 1.5707963267948966</pose>
      <geometry>
        <box>
          <size>0.1 0.055 0.048 </size>
        </box>
      </geometry>
    </collision>



    <collision name="rail_35_right">
      <pose>-5.4505 -3.52 2.612 0 0.29 1.5707963267948966</pose>
      <geometry>
        <box>
          <size>0.1 0.055 0.048 </size>
        </box>
      </geometry>
    </collision>

    <!-- Small module entrance door collisions -->



    <collision name="entrance_left">
      <pose>-7.447 -1.175 2.9 0 0 0</pose>
      <geometry>
        <box>
          <size>0.16 0.5 2.2 </size>
        </box>
      </geometry>
      <surface>
        <contact>
          <!-- Don't collide with door -->
          <collide_bitmask>0x01</collide_bitmask>
        </contact>
      </surface>
    </collision>



    <collision name="entrance_right">
      <pose>-5.923 -1.276 2.9 0 0 0</pose>
      <geometry>
        <box>
          <size>0.16 0.3 2.2 </size>
        </box>
      </geometry>
      <surface>
        <contact>
          <!-- Don't collide with door -->
          <collide_bitmask>0x01</collide_bitmask>
        </contact>
      </surface>
    </collision>



    <!-- Small module wall collisions -->

    <collision name="wall_1">
      <pose>-7.8 -0.475 2.9 0 0 0.495</pose>
      <geometry>
        <box>
          <size>0.16 1.2 2.2 </size>
        </box>
      </geometry>
    </collision>



    <collision name="wall_2">
      <pose>-7.76 0.505 2.9 0 0 -0.525</pose>
      <geometry>
        <box>
          <size>0.16 1.5 2.2 </size>
        </box>
      </geometry>
    </collision>



    <collision name="wall_3">
      <pose>-6.69 1.185 2.9 0 0 1.5707963267948966</pose>
      <geometry>
        <box>
          <size>0.16 1.5 2.2 </size>
        </box>
      </geometry>
    </collision>



    <collision name="wall_4">
      <pose>-5.89 1.0 2.9 0 0 0.525</pose>
      <geometry>
        <box>
          <size>0.16 0.5 2.2 </size>
        </box>
      </geometry>
    </collision>



    <collision name="wall_5">
      <pose>-5.93 -1.04 2.9 0 0 -0.525</pose>
      <geometry>
        <box>
          <size>0.16 0.5 2.2 </size>
        </box>
      </geometry>
      <surface>
        <contact>
          <!-- Don't collide with door -->
          <collide_bitmask>0x01</collide_bitmask>
        </contact>
      </surface>
    </collision>

    <!-- Passage collisions -->



    <collision name="passage_left">
      <pose>-5.295 0.928 2.9 0 0 0</pose>
      <geometry>
        <box>
          <size>0.845 0.5 2.2 </size>
        </box>
      </geometry>
    </collision>



    <collision name="passage_right">
      <pose>-5.295 -0.93 2.9 0 0 0</pose>
      <geometry>
        <box>
          <size>0.845 0.5 2.2 </size>
        </box>
      </geometry>
    </collision>

    <!-- Large module wall collisions -->



    <collision name="wall_6">
      <pose>-4.905 1.798 2.9 0 0 0</pose>
      <geometry>
        <box>
          <size>0.1 2.23 2.2 </size>
        </box>
      </geometry>
    </collision>



    <collision name="wall_7">
      <pose>-2.681 4.28 2.9 0 0 -1.047</pose>
      <geometry>
        <box>
          <size>0.1 5.73 2.2 </size>
        </box>
      </geometry>
    </collision>



    <collision name="wall_8">
      <pose>2.46 4.28 2.9 0 0 1.049</pose>
      <geometry>
        <box>
          <size>0.1 5.73 2.2 </size>
        </box>
      </geometry>
    </collision>



    <collision name="wall_9">
      <pose>5.0 1.798 2.9 0 0 0.0</pose>
      <geometry>
        <box>
          <size>0.32 2.23 2.2 </size>
        </box>
      </geometry>
    </collision>



    <collision name="wall_10">
      <pose>5.0 -1.798 2.9 0 0 0.0</pose>
      <geometry>
        <box>
          <size>0.32 2.23 2.2 </size>
        </box>
      </geometry>
    </collision>



    <collision name="wall_11">
      <pose>2.46 -4.28 2.9 0 0 -1.049</pose>
      <geometry>
        <box>
          <size>0.1 5.73 2.2 </size>
        </box>
      </geometry>
    </collision>



    <collision name="wall_12">
      <pose>-2.46 -4.28 2.9 0 0 1.049</pose>
      <geometry>
        <box>
          <size>0.1 5.73 2.2 </size>
        </box>
      </geometry>
    </collision>



    <collision name="wall_13">
      <pose>-5.0 -1.798 2.9 0 0 0.0</pose>
      <geometry>
        <box>
          <size>0.32 2.23 2.2 </size>
        </box>
      </geometry>
    </collision>

    <!-- Passage collisions -->



    <collision name="passage_2_left">
      <pose>5.295 0.928 2.9 0 0 0</pose>
      <geometry>
        <box>
          <size>0.845 0.5 2.2 </size>
        </box>
      </geometry>
    </collision>



    <collision name="passage_2_right">
      <pose>5.295 -0.93 2.9 0 0 0</pose>
      <geometry>
        <box>
          <size>0.845 0.5 2.2 </size>
        </box>
      </geometry>
    </collision>

    <!-- Long module -->



    <collision name="wall_14">
      <pose>8.919 1.161 2.3537 -0.518 0 0.0</pose>
      <geometry>
        <box>
          <size>6.159 0.1319 2.16955 </size>
        </box>
      </geometry>
    </collision>



    <collision name="wall_15">
      <pose>8.919 -1.161 2.3537 0.518 0 0.0</pose>
      <geometry>
        <box>
          <size>6.159 0.1319 2.16955 </size>
        </box>
      </geometry>
    </collision>

    <!-- VISUALS -->

    <visual name="stairs">
      <pose>0 0 0 0 0 0</pose>
      <geometry>
        <mesh>
          <uri>model://src_habitat/meshes/hdu.obj</uri>
          <scale>0.0254 0.0254 0.0254</scale>
          <submesh>
            <name>Stairs</name>
          </submesh>
        </mesh>
      </geometry>
    </visual>

    <visual name="module_small">
      <pose>0 0 0 0 0 0</pose>
      <geometry>
        <mesh>
          <uri>model://src_habitat/meshes/hdu.obj</uri>
          <scale>0.0254 0.0254 0.0254</scale>
          <submesh>
            <name>Module_Small</name>
          </submesh>
        </mesh>
      </geometry>
    </visual>

    <visual name="door_01">
      <pose>0 0 0 0 0 0</pose>
      <geometry>
        <mesh>
          <uri>model://src_habitat/meshes/hdu.obj</uri>
          <scale>0.0254 0.0254 0.0254</scale>
          <submesh>
            <name>Door_01</name>
          </submesh>
        </mesh>
      </geometry>
    </visual>

    <visual name="door_03">
      <geometry>
        <mesh>
          <uri>model://src_habitat/meshes/hdu.obj</uri>
          <scale>0.0254 0.0254 0.0254</scale>
          <submesh>
            <name>Door_03</name>
          </submesh>
        </mesh>
      </geometry>
    </visual>

    <visual name="door_04">
      <pose>0 0 0 0 0 0</pose>
      <geometry>
        <mesh>
          <uri>model://src_habitat/meshes/hdu.obj</uri>
          <scale>0.0254 0.0254 0.0254</scale>
          <submesh>
            <name>Door_04</name>
          </submesh>
        </mesh>
      </geometry>
    </visual>

    <visual name="module_large">
      <pose>0 0 0 0 0 0</pose>
      <geometry>
        <mesh>
          <uri>model://src_habitat/meshes/hdu.obj</uri>
          <scale>0.0254 0.0254 0.0254</scale>
          <submesh>
            <name>Module_Large</name>
          </submesh>
        </mesh>
      </geometry>
    </visual>

    <visual name="module_long">
      <pose>0 0 0 0 0 0</pose>
      <geometry>
        <mesh>
          <uri>model://src_habitat/meshes/hdu.obj</uri>
          <scale>0.0254 0.0254 0.0254</scale>
          <submesh>
            <name>Module_Long</name>
          </submesh>
        </mesh>
      </geometry>
    </visual>

    <visual name="finish_box">
      <pose>9.0 0.0 1.814 0 0 0</pose>
      <geometry>
        <box>
          <size>1.5 1.5 0.01 </size>
        </box>
      </geometry>
      <material>
        <script>
          <uri>model://src_habitat/materials/scripts</uri>
          <uri>model://src_habitat/materials/textures</uri>
          <name>FinishBox</name>
        </script>
      </material>
    </visual>

  </link>
</model>

<!-- Door -->
<model name="habitat_door">

  <pose>
    17.954322358147756
    13.210810334859856
    2.88
    0
    0
    -0.7853981633974487
  </pose>

  <!-- door body -->
  <link name="base">

    <inertial>
      <mass>18</mass>
      <inertia>
        <ixx>6.304</ixx>
        <ixy>0</ixy>
        <ixz>0</ixz>
        <iyy>6.9932</iyy>
        <iyz>0</iyz>
        <izz>0.7979</izz>
      </inertia>
    </inertial>

    <collision name="collision">
      <geometry>
        <box>
          <size>1.27 0.25 1.99</size>
        </box>
      </geometry>
      <surface>
        <contact>
          <!-- Don't collide with habitat -->
          <collide_bitmask>0x10</collide_bitmask>
        </contact>
      </surface>
    </collision>

    <visual name="visual">
      <pose>6.68 1.215 -2.88 0 0 0</pose>
      <geometry>
        <mesh>
          <uri>model://src_habitat/meshes/hdu.obj</uri>
          <scale>0.0254 0.0254 0.0254</scale>
          <submesh>
            <name>Door_02</name>
          </submesh>
        </mesh>
      </geometry>
    </visual>
  </link>

  <!-- door valve -->
  <link name="valve">
    <pose>0 -0.12 0.08 0 0 3.14</pose>
    <inertial>
      <mass>7.8219</mass>
      <pose>0 0.0615 0 0 0 0</pose>
      <inertia>
        <ixx>0.0695</ixx>
        <ixy>0.0000</ixy>
        <ixz>0.0000</ixz>
        <iyy>0.1349</iyy>
        <iyz>0.0000</iyz>
        <izz>0.0695</izz>
      </inertia>
    </inertial>

    <collision name="center">
      <pose>0 0.045 0 1.57 0 0</pose>
      <geometry>
        <cylinder>
          <length>0.09</length>
          <radius>0.038</radius>
        </cylinder>
      </geometry>
      <surface>
        <friction>
          <ode>
            <mu>1</mu>
            <mu2>1</mu2>
          </ode>
        </friction>
        <contact>
          <ode>
            <kp>1000000.0</kp>
            <kd>100.0</kd>
            <max_vel>0.01</max_vel>
            <min_depth>0.001</min_depth>
          </ode>
        </contact>
      </surface>

    </collision>



    <collision name="circle_0">
      <pose>0.15 0.065 0.0 0 -0.0 0</pose>
      <geometry>
        <cylinder>
          <length>0.092</length>
          <radius>0.022</radius>
        </cylinder>
      </geometry>
      <surface>
        <friction>
          <ode>
            <mu>1</mu>
            <mu2>1</mu2>
          </ode>
        </friction>
        <contact>
          <ode>
            <kp>1000000.0</kp>
            <kd>100.0</kd>
            <max_vel>0.01</max_vel>
            <min_depth>0.001</min_depth>
          </ode>
        </contact>
      </surface>

    </collision>



    <collision name="circle_1">
      <pose>0.1299038105676658 0.065 0.07499999999999998 0 -0.5235987755982988 0</pose>
      <geometry>
        <cylinder>
          <length>0.092</length>
          <radius>0.022</radius>
        </cylinder>
      </geometry>
      <surface>
        <friction>
          <ode>
            <mu>1</mu>
            <mu2>1</mu2>
          </ode>
        </friction>
        <contact>
          <ode>
            <kp>1000000.0</kp>
            <kd>100.0</kd>
            <max_vel>0.01</max_vel>
            <min_depth>0.001</min_depth>
          </ode>
        </contact>
      </surface>

    </collision>



    <collision name="circle_2">
      <pose>0.07500000000000001 0.065 0.12990381056766578 0 -1.0471975511965976 0</pose>
      <geometry>
        <cylinder>
          <length>0.092</length>
          <radius>0.022</radius>
        </cylinder>
      </geometry>
      <surface>
        <friction>
          <ode>
            <mu>1</mu>
            <mu2>1</mu2>
          </ode>
        </friction>
        <contact>
          <ode>
            <kp>1000000.0</kp>
            <kd>100.0</kd>
            <max_vel>0.01</max_vel>
            <min_depth>0.001</min_depth>
          </ode>
        </contact>
      </surface>

    </collision>



    <collision name="circle_3">
      <pose>9.184850993605149e-18 0.065 0.15 0 -1.5707963267948966 0</pose>
      <geometry>
        <cylinder>
          <length>0.092</length>
          <radius>0.022</radius>
        </cylinder>
      </geometry>
      <surface>
        <friction>
          <ode>
            <mu>1</mu>
            <mu2>1</mu2>
          </ode>
        </friction>
        <contact>
          <ode>
            <kp>1000000.0</kp>
            <kd>100.0</kd>
            <max_vel>0.01</max_vel>
            <min_depth>0.001</min_depth>
          </ode>
        </contact>
      </surface>

    </collision>



    <collision name="circle_4">
      <pose>-0.07499999999999997 0.065 0.1299038105676658 0 -2.0943951023931953 0</pose>
      <geometry>
        <cylinder>
          <length>0.092</length>
          <radius>0.022</radius>
        </cylinder>
      </geometry>
      <surface>
        <friction>
          <ode>
            <mu>1</mu>
            <mu2>1</mu2>
          </ode>
        </friction>
        <contact>
          <ode>
            <kp>1000000.0</kp>
            <kd>100.0</kd>
            <max_vel>0.01</max_vel>
            <min_depth>0.001</min_depth>
          </ode>
        </contact>
      </surface>

    </collision>



    <collision name="circle_5">
      <pose>-0.12990381056766576 0.065 0.07500000000000005 0 -2.617993877991494 0</pose>
      <geometry>
        <cylinder>
          <length>0.092</length>
          <radius>0.022</radius>
        </cylinder>
      </geometry>
      <surface>
        <friction>
          <ode>
            <mu>1</mu>
            <mu2>1</mu2>
          </ode>
        </friction>
        <contact>
          <ode>
            <kp>1000000.0</kp>
            <kd>100.0</kd>
            <max_vel>0.01</max_vel>
            <min_depth>0.001</min_depth>
          </ode>
        </contact>
      </surface>

    </collision>



    <collision name="circle_6">
      <pose>-0.15 0.065 1.8369701987210297e-17 0 -3.141592653589793 0</pose>
      <geometry>
        <cylinder>
          <length>0.092</length>
          <radius>0.022</radius>
        </cylinder>
      </geometry>
      <surface>
        <friction>
          <ode>
            <mu>1</mu>
            <mu2>1</mu2>
          </ode>
        </friction>
        <contact>
          <ode>
            <kp>1000000.0</kp>
            <kd>100.0</kd>
            <max_vel>0.01</max_vel>
            <min_depth>0.001</min_depth>
          </ode>
        </contact>
      </surface>

    </collision>



    <collision name="circle_7">
      <pose>-0.1299038105676658 0.065 -0.07499999999999996 0 -3.665191429188092 0</pose>
      <geometry>
        <cylinder>
          <length>0.092</length>
          <radius>0.022</radius>
        </cylinder>
      </geometry>
      <surface>
        <friction>
          <ode>
            <mu>1</mu>
            <mu2>1</mu2>
          </ode>
        </friction>
        <contact>
          <ode>
            <kp>1000000.0</kp>
            <kd>100.0</kd>
            <max_vel>0.01</max_vel>
            <min_depth>0.001</min_depth>
          </ode>
        </contact>
      </surface>

    </collision>



    <collision name="circle_8">
      <pose>-0.07500000000000007 0.065 -0.12990381056766576 0 -4.1887902047863905 0</pose>
      <geometry>
        <cylinder>
          <length>0.092</length>
          <radius>0.022</radius>
        </cylinder>
      </geometry>
      <surface>
        <friction>
          <ode>
            <mu>1</mu>
            <mu2>1</mu2>
          </ode>
        </friction>
        <contact>
          <ode>
            <kp>1000000.0</kp>
            <kd>100.0</kd>
            <max_vel>0.01</max_vel>
            <min_depth>0.001</min_depth>
          </ode>
        </contact>
      </surface>

    </collision>



    <collision name="circle_9">
      <pose>-2.7554552980815445e-17 0.065 -0.15 0 -4.71238898038469 0</pose>
      <geometry>
        <cylinder>
          <length>0.092</length>
          <radius>0.022</radius>
        </cylinder>
      </geometry>
      <surface>
        <friction>
          <ode>
            <mu>1</mu>
            <mu2>1</mu2>
          </ode>
        </friction>
        <contact>
          <ode>
            <kp>1000000.0</kp>
            <kd>100.0</kd>
            <max_vel>0.01</max_vel>
            <min_depth>0.001</min_depth>
          </ode>
        </contact>
      </surface>

    </collision>



    <collision name="circle_10">
      <pose>0.0749999999999999 0.065 -0.12990381056766584 0 -5.235987755982988 0</pose>
      <geometry>
        <cylinder>
          <length>0.092</length>
          <radius>0.022</radius>
        </cylinder>
      </geometry>
      <surface>
        <friction>
          <ode>
            <mu>1</mu>
            <mu2>1</mu2>
          </ode>
        </friction>
        <contact>
          <ode>
            <kp>1000000.0</kp>
            <kd>100.0</kd>
            <max_vel>0.01</max_vel>
            <min_depth>0.001</min_depth>
          </ode>
        </contact>
      </surface>

    </collision>



    <collision name="circle_11">
      <pose>0.12990381056766576 0.065 -0.07500000000000007 0 -5.759586531581287 0</pose>
      <geometry>
        <cylinder>
          <length>0.092</length>
          <radius>0.022</radius>
        </cylinder>
      </geometry>
      <surface>
        <friction>
          <ode>
            <mu>1</mu>
            <mu2>1</mu2>
          </ode>
        </friction>
        <contact>
          <ode>
            <kp>1000000.0</kp>
            <kd>100.0</kd>
            <max_vel>0.01</max_vel>
            <min_depth>0.001</min_depth>
          </ode>
        </contact>
      </surface>

    </collision>





    <collision name="cross_0">
      <pose>0.0 0.065 0.0 0 -0.0 0</pose>
      <geometry>
        <box>
          <size>0.3 0.03 0.042</size>
        </box>
      </geometry>
      <surface>
        <friction>
          <ode>
            <mu>1</mu>
            <mu2>1</mu2>
          </ode>
        </friction>
        <contact>
          <ode>
            <kp>1000000.0</kp>
            <kd>100.0</kd>
            <max_vel>0.01</max_vel>
            <min_depth>0.001</min_depth>
          </ode>
        </contact>
      </surface>

    </collision>



    <collision name="cross_1">
      <pose>0.0 0.065 0.0 0 -1.5707963267948966 0</pose>
      <geometry>
        <box>
          <size>0.3 0.03 0.042</size>
        </box>
      </geometry>
      <surface>
        <friction>
          <ode>
            <mu>1</mu>
            <mu2>1</mu2>
          </ode>
        </friction>
        <contact>
          <ode>
            <kp>1000000.0</kp>
            <kd>100.0</kd>
            <max_vel>0.01</max_vel>
            <min_depth>0.001</min_depth>
          </ode>
        </contact>
      </surface>

    </collision>



    <visual name="visual">
      <geometry>
        <mesh>
          <uri>model://src_habitat/meshes/wheel_valve_large.dae</uri>
        </mesh>
      </geometry>
    </visual>
  </link>

  <!-- Joint connecting the valve and the door -->
  <joint name="valve_hinge" type="revolute">
    <parent>base</parent>
    <child>valve</child>
    <axis>
      <xyz>0 1 0</xyz>
      <limit>
        <lower>0</lower>
        <upper>6.5973445725385655</upper>
      </limit>
      <dynamics>
        <friction>1.1277775237871126</friction>
        <damping>0.04675100370746795</damping>
      </dynamics>
    </axis>
  </joint>

  <!-- Door hinge -->
  <joint name="door_hinge" type="revolute">
    <parent>world</parent>
    <child>base</child>
    <pose>-0.8 0.125 0.2 0 0 0</pose>
    <axis>
      <xyz>0 0 1</xyz>
      <limit>
        <lower>0</lower>
        <upper>1.57</upper>
      </limit>
      <dynamics>
        <friction>14.798081466003001</friction>
        <damping>2.7761507460763823</damping>
      </dynamics>
    </axis>
  </joint>

  <!-- Door lock -->
  <joint name="door_lock" type="fixed">
    <parent>world</parent>
    <child>base</child>
  </joint>

</model>



    <!-- Checkpoint 1 - Climb the stairs -->


    <plugin name="boxT3CP1" filename="libBoxContainsPlugin.so">
      <entity>valkyrie</entity>
      <namespace>task3/checkpoint1</namespace>
      <pose>
        16.607283939987383
        11.863771916699484
        2.92
        0
        0
        0.785398163397448
      </pose>
      <size>1.0 2.50 2.44</size>
    </plugin>

    <!-- Checkpoint 3 - Pass through the door -->


    <plugin name="boxT3CP3" filename="libBoxContainsPlugin.so">
      <entity>valkyrie</entity>
      <namespace>task3/checkpoint3</namespace>
      <pose>
        20.36895059454358
        12.542453005282331
        2.81
        0
        0
        -0.7853981633974487
      </pose>
      <size>1.00 1.55 2.88</size>
    </plugin>





    <!-- Checkpoint 8 - Box plugin -->


    <plugin name="boxT3CP8" filename="libBoxContainsPlugin.so">
      <entity>valkyrie</entity>
      <namespace>task3/checkpoint8</namespace>
      <pose>
        29.900891426294475
        2.982510744996442
        2.68
        0
        0
        -0.7853981633974487
      </pose>
      <size>1.5 1.5 5.0</size>
    </plugin>

    <!-- /TASK 3 -->


    <!-- Finals plugin -->
    <plugin name="finals" filename="libFinalsPlugin.so">


        <task1>
          <timeout>1800</timeout>

          <checkpoint1>
            <skip_robot_pose>
              2.3866949400811337
              -0.4506735555415058
              1.257
              0
              0
              -1.570796326794897
            </skip_robot_pose>
          </checkpoint1>

          <checkpoint2>
            <skip_robot_pose>
              2.3866949400811337
              -0.4506735555415058
              1.257
              0
              0
              -1.570796326794897
            </skip_robot_pose>
          </checkpoint2>

          <!-- checkpoint 3 copies checkpoint 2's skip pose -->

          <checkpoint4>
            <skip_robot_pose>
              5.069995469056598
              2.694731561056596
              1.257
              0
              0
              0.7853981633974481
            </skip_robot_pose>
          </checkpoint4>
        </task1>



        <task2>
          <timeout>3600</timeout>

          <checkpoint1>
            <start_robot_pose>
              5.069995469056598
              2.694731561056596
              1.257
              0
              0
              0.7853981633974481
            </start_robot_pose>
            <skip_robot_pose>
              5.069995469056598
              2.694731561056596
              1.257
              0
              0
              0.7853981633974481
            </skip_robot_pose>
          </checkpoint1>

          <checkpoint2>
            <skip_robot_pose>
              8.762641309503824
              9.593959149090667
              1.257
              0
              0
              2.356194490192345
            </skip_robot_pose>
            <panel_pose>
              7.788859246319888
              10.07886557550421
              0.8999999999999999
              0
              0
              1.6572816059233577
            </panel_pose>
          </checkpoint2>

          <checkpoint3>
            <skip_robot_pose>
              8.762641309503824
              9.593959149090667
              1.257
              0
              0
              2.356194490192345
            </skip_robot_pose>
          </checkpoint3>

          <checkpoint4>
            <skip_robot_pose>
              8.762641309503824
              9.593959149090667
              1.257
              0
              0
              2.356194490192345
            </skip_robot_pose>
          </checkpoint4>

          <checkpoint5>
            <skip_robot_pose>
              8.762641309503824
              9.593959149090667
              1.257
              0
              0
              2.356194490192345
            </skip_robot_pose>
          </checkpoint5>

          <checkpoint6>
            <skip_robot_pose>
              11.535914105317465
              12.208840025918521
              1.257
              0
              0
              -0.7853981633974485
            </skip_robot_pose>
          </checkpoint6>

        </task2>




        <task3>
          <timeout>7200</timeout>

          <checkpoint1>
            <start_robot_pose>
              11.535914105317465
              12.208840025918521
              1.257
              0
              0
              -0.7853981633974485
            </start_robot_pose>
            <skip_robot_pose>
              16.607283939987383
              11.863771916699484
              2.957
              0
              0
              0.785398163397448
            </skip_robot_pose>
          </checkpoint1>

          <checkpoint2>
            <skip_robot_pose>
              16.607283939987383
              11.863771916699484
              2.957
              0
              0
              0.785398163397448
            </skip_robot_pose>
          </checkpoint2>

          <checkpoint3>

            <!-- Lamp inside the habitat -->
            <insert_entity>

              <light name='habitat_lamp' type='spot'>
                <pose>
                  20.056550818615364
                  13.163434180520357
                  4.2
                  -1.462
                  0
                  0.785398163397448
                </pose>
                <diffuse>1 1 1 1</diffuse>
                <specular>0.1 0.1 0.1 1</specular>
                <attenuation>
                  <range>10</range>
                  <constant>0.5</constant>
                  <linear>0.01</linear>
                  <quadratic>0.001</quadratic>
                </attenuation>
                <cast_shadows>0</cast_shadows>
                <direction>0 0 -1</direction>
                <spot>
                  <inner_angle>0.6</inner_angle>
                  <outer_angle>3.141592653589793</outer_angle>
                  <falloff>0.5</falloff>
                </spot>
              </light>

            </insert_entity>

            <!-- Table -->
            <insert_entity>

                <include>
                  <pose>
                    23.77882739292403
                    9.693145421933933
                    2.0
                    0
                    0
                    1.6718356642053744
                  </pose>
                  <uri>model://space_table</uri>
                </include>
            </insert_entity>

            <!-- Air leak detector -->
            <insert_entity>




<model name="air_leak_detector">

  <pose>
    23.451214457818338
    9.95864174754969
    2.79448
    0
    0
    4.204132244395506
  </pose>

  <link name="base">

    <inertial>
      <pose>
      0
      -0.00063
      0
      0
      0
      0
      </pose>
      <inertia>
        <ixx>0.0006035883333333333</ixx>
        <iyy>0.003206729933333333</iyy>
        <izz>0.003333989666666666</izz>
      </inertia>
      <mass>1.0</mass>
    </inertial>


    <collision name="collision">

      <pose>0 0 -0.022000000000000002 0 0 -1.5707963267948966</pose>

      <geometry>
        <mesh>
          <scale>0.02 0.02 0.02</scale>
          <uri>model://air_leak_detector/meshes/air_leak_detector.obj</uri>
        </mesh>
      </geometry>
      <surface>
        <contact>
          <ode>
            <kp>1e5</kp>
            <kd>1</kd>
            <max_vel>0.1</max_vel>
            <min_depth>0.0015</min_depth>
          </ode>
        </contact>
      </surface>
    </collision>

    <visual name="visual">

      <pose>0 0 -0.022000000000000002 0 0 -1.5707963267948966</pose>

      <geometry>
        <mesh>
          <scale>0.02 0.02 0.02</scale>
          <uri>model://air_leak_detector/meshes/air_leak_detector.obj</uri>
        </mesh>
      </geometry>
    </visual>

    <sensor name="logical_camera" type="logical_camera">

      <logical_camera>
        <near>0.2</near>
        <far>0.5</far>
        <horizontal_fov>0.3490658503988659</horizontal_fov>
        <aspect_ratio>1</aspect_ratio>
      </logical_camera>

      <visualize>true</visualize>
      <always_on>true</always_on>
      <update_rate>10</update_rate>

    </sensor>

    <sensor name="contact_sensor" type="contact">
      <contact>
        <collision>collision</collision>
      </contact>
    </sensor>

  </link>

  <plugin name="touch_valkyrie_detector" filename="libTouchPlugin.so">
    <sensor>contact_sensor</sensor>
    <target>valkyrie</target>
    <time>0.5</time>
    <namespace>task3/checkpoint4</namespace>
  </plugin>

</model>


            </insert_entity>

            <!-- Leak patch tool -->
            <insert_entity>


                <include>
                  <pose>
                    23.586814096120616
                    9.52051377860908
                    2.8000000000000003
                    0
                    0
                    -1.7592893200402153
                  </pose>
                  <uri>model://leak_patch_tool</uri>
                </include>
            </insert_entity>

            <!-- Leak -->
            <insert_entity>


<model name="leak">
  <static>true</static>

  <pose>27.130462605180625 13.56054805055506 3.1422858967838323 0 0 0</pose>

  <link name="base">

    <collision name="collision">

      <geometry>
        <sphere>
          <radius>0.02</radius>
        </sphere>
      </geometry>

      <surface>
        <contact>
          <!-- Only collide with patch tool -->
          <collide_bitmask>0x10000</collide_bitmask>
        </contact>
      </surface>

    </collision>

    <sensor name="leak_sensor" type="contact">
      <contact>
        <collision>collision</collision>
      </contact>
    </sensor>

  </link>

</model>


            </insert_entity>

            <!-- Bling -->

            <insert_entity>
    <include>
      <name>mars_crate_long_15</name>
      <pose>
      27.114746574565206
      10.115150805526424
      1.8
      0
      0
      0.11317446840766053
      </pose>
      <uri>model://mars_crate_long</uri>
    </include>
    </insert_entity>



            <!-- Bling -->

            <insert_entity>
    <include>
      <name>mars_crate_long_16</name>
      <pose>
      26.068783676823667
      7.720769367010113
      1.8
      0
      0
      1.573103223496502
      </pose>
      <uri>model://mars_crate_long</uri>
    </include>
    </insert_entity>


            <insert_entity>
    <include>
      <name>mars_crate_long_17</name>
      <pose>
      26.068783676823667
      7.720769367010113
      2.5
      0
      0
      1.0917159072456117
      </pose>
      <uri>model://mars_crate_long</uri>
    </include>
    </insert_entity>


            <insert_entity>
    <include>
      <name>mars_crate_long_18</name>
      <pose>
      26.068783676823667
      7.720769367010113
      3.2
      0
      0
      0.6829664520037306
      </pose>
      <uri>model://mars_crate_long</uri>
    </include>
    </insert_entity>



            <!-- Bling -->

            <insert_entity>
    <include>
      <name>mars_crate_19</name>
      <pose>
      24.42793119830642
      5.5508740111910715
      1.8
      0
      0
      0.3288985311688958
      </pose>
      <uri>model://mars_crate</uri>
    </include>
    </insert_entity>



            <!-- Bling -->

            <insert_entity>
    <include>
      <name>mars_crate_long_20</name>
      <pose>
      21.20018787225451
      6.811650594767965
      1.8
      0
      0
      1.428451940366459
      </pose>
      <uri>model://mars_crate_long</uri>
    </include>
    </insert_entity>


            <insert_entity>
    <include>
      <name>mars_crate_long_21</name>
      <pose>
      21.20018787225451
      6.811650594767965
      2.5
      0
      0
      1.0338952609388918
      </pose>
      <uri>model://mars_crate_long</uri>
    </include>
    </insert_entity>


            <insert_entity>
    <include>
      <name>mars_crate_long_22</name>
      <pose>
      21.20018787225451
      6.811650594767965
      3.2
      0
      0
      0.7496098600860759
      </pose>
      <uri>model://mars_crate_long</uri>
    </include>
    </insert_entity>



            <!-- Bling -->

            <insert_entity>
    <include>
      <name>mars_crate_long_23</name>
      <pose>
      19.807984192530206
      9.480769556190799
      1.8
      0
      0
      -0.27836074921821496
      </pose>
      <uri>model://mars_crate_long</uri>
    </include>
    </insert_entity>


            <insert_entity>
    <include>
      <name>mars_crate_long_24</name>
      <pose>
      19.807984192530206
      9.480769556190799
      2.5
      0
      0
      0.3331166561270132
      </pose>
      <uri>model://mars_crate_long</uri>
    </include>
    </insert_entity>


            <insert_entity>
    <include>
      <name>mars_crate_long_25</name>
      <pose>
      19.807984192530206
      9.480769556190799
      3.2
      0
      0
      0.37021254082978233
      </pose>
      <uri>model://mars_crate_long</uri>
    </include>
    </insert_entity>



            <!-- Bling -->

            <insert_entity>
    <include>
      <name>mars_crate_26</name>
      <pose>
      22.02475339748585
      12.405827973661255
      1.8
      0
      0
      2.835264719516869
      </pose>
      <uri>model://mars_crate</uri>
    </include>
    </insert_entity>


            <insert_entity>
    <include>
      <name>mars_crate_27</name>
      <pose>
      22.02475339748585
      12.405827973661255
      2.5
      0
      0
      3.085201768527324
      </pose>
      <uri>model://mars_crate</uri>
    </include>
    </insert_entity>


            <insert_entity>
    <include>
      <name>mars_crate_28</name>
      <pose>
      22.02475339748585
      12.405827973661255
      3.2
      0
      0
      -2.75988067788253
      </pose>
      <uri>model://mars_crate</uri>
    </include>
    </insert_entity>



            <!-- Bling -->

            <insert_entity>
    <include>
      <name>mars_crate_long_29</name>
      <pose>
      24.36313996625677
      12.808462700886576
      1.8
      0
      0
      1.5379326637611523
      </pose>
      <uri>model://mars_crate_long</uri>
    </include>
    </insert_entity>


            <insert_entity>
    <include>
      <name>mars_crate_long_30</name>
      <pose>
      24.36313996625677
      12.808462700886576
      2.5
      0
      0
      1.9244529937709207
      </pose>
      <uri>model://mars_crate_long</uri>
    </include>
    </insert_entity>



            <skip_robot_pose>
              20.36895059454358
              12.542453005282331
              2.957
              0
              0
              -0.7853981633974487
            </skip_robot_pose>
          </checkpoint3>

          <checkpoint4>
            <delete_entity>satellite_dish</delete_entity>
            <delete_entity>solar_panel</delete_entity>
            <delete_entity>solar_panel_cable</delete_entity>
            <delete_entity>solar_array</delete_entity>
            <delete_entity>mars_explorer</delete_entity>

              <delete_entity>walkway_1</delete_entity>

              <delete_entity>walkway_2</delete_entity>

              <delete_entity>walkway_3</delete_entity>

              <delete_entity>walkway_4</delete_entity>

              <delete_entity>walkway_5</delete_entity>

              <delete_entity>walkway_6</delete_entity>

              <delete_entity>walkway_7</delete_entity>

              <delete_entity>walkway_8</delete_entity>

              <delete_entity>walkway_9</delete_entity>

              <delete_entity>walkway_10</delete_entity>

              <delete_entity>walkway_11</delete_entity>

              <delete_entity>walkway_12</delete_entity>

              <delete_entity>walkway_13</delete_entity>


              <delete_entity>bling_1</delete_entity>

              <delete_entity>bling_2</delete_entity>

              <delete_entity>bling_3</delete_entity>

              <delete_entity>bling_4</delete_entity>

              <delete_entity>bling_5</delete_entity>

              <delete_entity>bling_6</delete_entity>

              <delete_entity>bling_7</delete_entity>

              <delete_entity>bling_8</delete_entity>

              <delete_entity>bling_9</delete_entity>

              <delete_entity>bling_10</delete_entity>

              <delete_entity>bling_11</delete_entity>

              <delete_entity>bling_12</delete_entity>

              <delete_entity>bling_13</delete_entity>

              <delete_entity>bling_14</delete_entity>

            <skip_robot_pose>
              20.36895059454358
              12.542453005282331
              2.957
              0
              0
              -0.7853981633974487
            </skip_robot_pose>
          </checkpoint4>

          <checkpoint5>
            <skip_robot_pose>
              20.36895059454358
              12.542453005282331
              2.957
              0
              0
              -0.7853981633974487
            </skip_robot_pose>
          </checkpoint5>

          <checkpoint6>
            <skip_robot_pose>
              20.36895059454358
              12.542453005282331
              2.957
              0
              0
              -0.7853981633974487
            </skip_robot_pose>
          </checkpoint6>

          <checkpoint7>
            <skip_robot_pose>
              20.36895059454358
              12.542453005282331
              2.957
              0
              0
              -0.7853981633974487
            </skip_robot_pose>
          </checkpoint7>

          <checkpoint8>
            <skip_robot_pose>
              29.900891426294475
              2.982510744996442
              2.957
              0
              0
              -0.7853981633974487
            </skip_robot_pose>
          </checkpoint8>

        </task3>


    </plugin>

  </world>
</sdf>
