<?xml version="1.0" ?>
<sdf version="1.6">

  <model name="solar_panel">

    <allow_auto_disable>0</allow_auto_disable>
    <pose>
      7.82084699580533
      2.840805954908925
      0
      0
      0
      -4.0574162479713433e-16
    </pose>

    <link name="base">

      <inertial>
        <pose>
        0
        0
        0.04
        0
        0
        0
        </pose>
        <inertia>
          <ixx>0.002500000000000001</ixx>
          <iyy>0.03346720000000001</iyy>
          <izz>0.03496720000000001</izz>
        </inertia>
        <mass>2.4000000000000004</mass>
      </inertial>


      <collision name="collision">
        <geometry>
          <mesh>
            <uri>model://solar_panel/meshes/solar_panel.obj</uri>
            <submesh>
              <name>Base</name>
            </submesh>
            <scale>0.001 0.001 0.001</scale>
          </mesh>
        </geometry>
        <surface>
          <contact>
            <ode>
              <kp>1e6</kp>
              <kd>1</kd>
              <max_vel>0.1</max_vel>
              <min_depth>0.0015</min_depth>
            </ode>
          </contact>
        </surface>
      </collision>
      <visual name="visual">
        <geometry>
          <mesh>
            <uri>model://solar_panel/meshes/solar_panel.obj</uri>
            <submesh>
              <name>Base</name>
            </submesh>
            <scale>0.001 0.001 0.001</scale>
          </mesh>
        </geometry>
      </visual>
    </link>

    <link name="panel_01">

      <inertial>
        <pose>
        0
        0.05
        0.24
        0
        0
        0
        </pose>
        <inertia>
          <ixx>0.00237075</ixx>
          <iyy>0.005786083333333334</iyy>
          <izz>0.003452833333333334</izz>
        </inertia>
        <mass>0.25</mass>
      </inertial>


      <collision name="panel_collision">
        <geometry>
          <mesh>
            <uri>model://solar_panel/meshes/solar_panel.obj</uri>
            <submesh>
              <name>Panel_Large_01</name>
            </submesh>
            <scale>0.001 0.001 0.001</scale>
          </mesh>
        </geometry>
        <surface>
          <contact>
            <ode>
              <kp>1e6</kp>
              <kd>1</kd>
              <max_vel>0.1</max_vel>
              <min_depth>0.0015</min_depth>
            </ode>
          </contact>
        </surface>
      </collision>
      <visual name="panel_visual">
        <geometry>
          <mesh>
            <uri>model://solar_panel/meshes/solar_panel.obj</uri>
            <submesh>
              <name>Panel_Large_01</name>
            </submesh>
            <scale>0.001 0.001 0.001</scale>
          </mesh>
        </geometry>
      </visual>
      <collision name="button_housing_collision">
        <geometry>
          <mesh>
            <uri>model://solar_panel/meshes/solar_panel.obj</uri>
            <submesh>
              <name>ButtonHousing</name>
            </submesh>
            <scale>0.001 0.001 0.001</scale>
          </mesh>
        </geometry>
        <surface>
          <contact>
            <ode>
              <kp>1e6</kp>
              <kd>1</kd>
              <max_vel>0.1</max_vel>
              <min_depth>0.0015</min_depth>
            </ode>
          </contact>
        </surface>
      </collision>
      <visual name="button_housing_visual">
        <geometry>
          <mesh>
            <uri>model://solar_panel/meshes/solar_panel.obj</uri>
            <submesh>
              <name>ButtonHousing</name>
            </submesh>
            <scale>0.001 0.001 0.001</scale>
          </mesh>
        </geometry>
      </visual>
    </link>


    <link name="panel_02">

      <inertial>
        <pose>
        0
        -0.05
        0.24
        0
        0
        0
        </pose>
        <inertia>
          <ixx>0.00237075</ixx>
          <iyy>0.005786083333333334</iyy>
          <izz>0.003452833333333334</izz>
        </inertia>
        <mass>0.25</mass>
      </inertial>


      <collision name="collision">
        <geometry>
          <mesh>
            <uri>model://solar_panel/meshes/solar_panel.obj</uri>
            <submesh>
              <name>Panel_Large_02</name>
            </submesh>
            <scale>0.001 0.001 0.001</scale>
          </mesh>
        </geometry>
        <surface>
          <contact>
            <ode>
              <kp>1e6</kp>
              <kd>1</kd>
              <max_vel>0.1</max_vel>
              <min_depth>0.0015</min_depth>
            </ode>
          </contact>
        </surface>
      </collision>
      <visual name="visual">
        <geometry>
          <mesh>
            <uri>model://solar_panel/meshes/solar_panel.obj</uri>
            <submesh>
              <name>Panel_Large_02</name>
            </submesh>
            <scale>0.001 0.001 0.001</scale>
          </mesh>
        </geometry>
      </visual>
    </link>

    <link name="panel_small_01">

      <pose>0.2 0.03 0.2 0 0 0</pose>

      <inertial>
        <pose>
        -0.1
        -0.015
        0.005
        0
        0
        0
        </pose>
        <inertia>
          <ixx>0.0004852083333333333</ixx>
          <iyy>0.0008133333333333333</iyy>
          <izz>0.00033854166666666673</izz>
        </inertia>
        <mass>0.1</mass>
      </inertial>


      <collision name="collision">
        <pose>-0.2 -0.03 -0.2 0 0 0</pose>
        <geometry>
          <mesh>
            <uri>model://solar_panel/meshes/solar_panel.obj</uri>
            <submesh>
              <name>Panel_Small_01</name>
            </submesh>
            <scale>0.001 0.001 0.001</scale>
          </mesh>
        </geometry>
        <surface>
          <contact>
            <ode>
              <kp>1e6</kp>
              <kd>1</kd>
              <max_vel>0.1</max_vel>
              <min_depth>0.0015</min_depth>
            </ode>
          </contact>
        </surface>
      </collision>
      <visual name="visual">
        <pose>-0.2 -0.03 -0.2 0 0 0</pose>
        <geometry>
          <mesh>
            <uri>model://solar_panel/meshes/solar_panel.obj</uri>
            <submesh>
              <name>Panel_Small_01</name>
            </submesh>
            <scale>0.001 0.001 0.001</scale>
          </mesh>
        </geometry>
      </visual>
    </link>

    <link name="panel_small_02">

      <pose>0.2 -0.03 0.2 0 0 0</pose>

      <inertial>
        <pose>
        -0.1
        0.015
        0.005
        0
        0
        0
        </pose>
        <inertia>
          <ixx>0.0004852083333333333</ixx>
          <iyy>0.0008133333333333333</iyy>
          <izz>0.00033854166666666673</izz>
        </inertia>
        <mass>0.1</mass>
      </inertial>


      <collision name="collision">
        <pose>-0.2 0.03 -0.2 0 0 0</pose>
        <geometry>
          <mesh>
            <uri>model://solar_panel/meshes/solar_panel.obj</uri>
            <submesh>
              <name>Panel_Small_02</name>
            </submesh>
            <scale>0.001 0.001 0.001</scale>
          </mesh>
        </geometry>
        <surface>
          <contact>
            <ode>
              <kp>1e6</kp>
              <kd>1</kd>
              <max_vel>0.1</max_vel>
              <min_depth>0.0015</min_depth>
            </ode>
          </contact>
        </surface>
      </collision>
      <visual name="visual">
        <pose>-0.2 0.03 -0.2 0 0 0</pose>
        <geometry>
          <mesh>
            <uri>model://solar_panel/meshes/solar_panel.obj</uri>
            <submesh>
              <name>Panel_Small_02</name>
            </submesh>
            <scale>0.001 0.001 0.001</scale>
          </mesh>
        </geometry>
      </visual>
    </link>

    <link name="panel_small_03">

      <pose>-0.2 0.03 0.2 0 0 0</pose>

      <inertial>
        <pose>
        0.1
        -0.015
        0.005
        0
        0
        0
        </pose>
        <inertia>
          <ixx>0.0004852083333333333</ixx>
          <iyy>0.0008133333333333333</iyy>
          <izz>0.00033854166666666673</izz>
        </inertia>
        <mass>0.1</mass>
      </inertial>


      <collision name="collision">
        <pose>0.2 -0.03 -0.2 0 0 0</pose>
        <geometry>
          <mesh>
            <uri>model://solar_panel/meshes/solar_panel.obj</uri>
            <submesh>
              <name>Panel_Small_03</name>
            </submesh>
            <scale>0.001 0.001 0.001</scale>
          </mesh>
        </geometry>
        <surface>
          <contact>
            <ode>
              <kp>1e6</kp>
              <kd>1</kd>
              <max_vel>0.1</max_vel>
              <min_depth>0.0015</min_depth>
            </ode>
          </contact>
        </surface>
      </collision>
      <visual name="visual">
        <pose>0.2 -0.03 -0.2 0 0 0</pose>
        <geometry>
          <mesh>
            <uri>model://solar_panel/meshes/solar_panel.obj</uri>
            <submesh>
              <name>Panel_Small_03</name>
            </submesh>
            <scale>0.001 0.001 0.001</scale>
          </mesh>
        </geometry>
      </visual>
    </link>

    <link name="panel_small_04">

      <pose>-0.2 -0.03 0.2 0 0 0</pose>

      <inertial>
        <pose>
        0.1
        0.015
        0.005
        0
        0
        0
        </pose>
        <inertia>
          <ixx>0.0004852083333333333</ixx>
          <iyy>0.0008133333333333333</iyy>
          <izz>0.00033854166666666673</izz>
        </inertia>
        <mass>0.1</mass>
      </inertial>


      <collision name="collision">
        <pose>0.2 0.03 -0.2 0 0 0</pose>
        <geometry>
          <mesh>
            <uri>model://solar_panel/meshes/solar_panel.obj</uri>
            <submesh>
              <name>Panel_Small_04</name>
            </submesh>
            <scale>0.001 0.001 0.001</scale>
          </mesh>
        </geometry>
        <surface>
          <contact>
            <ode>
              <kp>1e6</kp>
              <kd>1</kd>
              <max_vel>0.1</max_vel>
              <min_depth>0.0015</min_depth>
            </ode>
          </contact>
        </surface>
      </collision>
      <visual name="visual">
        <pose>0.2 0.03 -0.2 0 0 0</pose>
        <geometry>
          <mesh>
            <uri>model://solar_panel/meshes/solar_panel.obj</uri>
            <submesh>
              <name>Panel_Small_04</name>
            </submesh>
            <scale>0.001 0.001 0.001</scale>
          </mesh>
        </geometry>
      </visual>
    </link>


    <link name="button">

      <pose>-0.155 0 0.4 0 0 0</pose>

      <inertial>
        <pose>
        0
        0
        0.017
        0
        0
        0
        </pose>
        <inertia>
          <ixx>4.8333333333333334e-05</ixx>
          <iyy>4.8333333333333334e-05</iyy>
          <izz>8.166666666666668e-05</izz>
        </inertia>
        <mass>0.1</mass>
      </inertial>


      <collision name="collision">
        <pose>0.155 0 -0.4 0 0 0</pose>
        <geometry>
          <mesh>
            <uri>model://solar_panel/meshes/solar_panel.obj</uri>
            <submesh>
              <name>Button</name>
            </submesh>
            <scale>0.001 0.001 0.001</scale>
          </mesh>
        </geometry>
        <surface>
          <contact>
            <ode>
              <kp>1e6</kp>
              <kd>1</kd>
              <max_vel>0.1</max_vel>
              <min_depth>0.0015</min_depth>
            </ode>
          </contact>
        </surface>
      </collision>
      <visual name="visual">
        <pose>0.155 0 -0.4 0 0 0</pose>
        <geometry>
          <mesh>
            <uri>model://solar_panel/meshes/solar_panel.obj</uri>
            <submesh>
              <name>Button</name>
            </submesh>
            <scale>0.001 0.001 0.001</scale>
          </mesh>
        </geometry>
      </visual>

      <sensor name="button_contact" type="contact">
        <contact>
          <collision>collision</collision>
        </contact>
      </sensor>

    </link>



    <joint name="base_panel_01" type="revolute">
      <pose>0 0.0455 0.095 0 0 0</pose>
      <parent>base</parent>
      <child>panel_01</child>
      <axis>
        <xyz>1 0 0</xyz>
        <limit>
         <lower>-1.5707963267948966</lower>
         <upper>0</upper>
        </limit>
        <dynamics>
          <damping>0.1</damping>
        </dynamics>
      </axis>
    </joint>

    <joint name="base_panel_02" type="revolute">
      <pose>0 -0.0455 0.095 0 0 0</pose>
      <parent>base</parent>
      <child>panel_02</child>
      <axis>
        <xyz>1 0 0</xyz>
        <limit>
         <lower>0</lower>
         <upper>1.5707963267948966</upper>
        </limit>
        <dynamics>
          <damping>0.1</damping>
        </dynamics>
      </axis>
    </joint>

    <joint name="panel_01_panel_small_01" type="revolute">
      <parent>panel_01</parent>
      <child>panel_small_01</child>
      <axis>
        <xyz>0 0 1</xyz>
        <limit>
         <lower>0</lower>
         <upper>3.141592653589793</upper>
        </limit>
        <dynamics>
          <damping>0.1</damping>
        </dynamics>
      </axis>
    </joint>

    <joint name="panel_02_panel_small_02" type="revolute">
      <parent>panel_02</parent>
      <child>panel_small_02</child>
      <axis>
        <xyz>0 0 1</xyz>
        <limit>
         <lower>-3.141592653589793</lower>
         <upper>0</upper>
        </limit>
        <dynamics>
          <damping>0.1</damping>
        </dynamics>
      </axis>
    </joint>

    <joint name="panel_01_panel_small_03" type="revolute">
      <parent>panel_01</parent>
      <child>panel_small_03</child>
      <axis>
        <xyz>0 0 1</xyz>
        <limit>
         <lower>-3.141592653589793</lower>
         <upper>0</upper>
        </limit>
        <dynamics>
          <damping>0.1</damping>
        </dynamics>
      </axis>
    </joint>

    <joint name="panel_02_panel_small_04" type="revolute">
      <parent>panel_02</parent>
      <child>panel_small_04</child>
      <axis>
        <xyz>0 0 1</xyz>
        <limit>
         <lower>0</lower>
         <upper>3.141592653589793</upper>
        </limit>
        <dynamics>
          <damping>0.1</damping>
        </dynamics>
      </axis>
    </joint>


    <joint name="button" type="prismatic">
      <pose>0 0 0.005 0 0 0</pose>
      <parent>panel_01</parent>
      <child>button</child>
      <axis>
        <xyz>0 0 1</xyz>
        <limit>
         <lower>-0.005</lower>
         <upper>0</upper>
        </limit>
        <dynamics>
          <damping>10</damping>
          <spring_stiffness>1000</spring_stiffness>
          <spring_reference>0</spring_reference>
        </dynamics>
      </axis>
    </joint>

    <joint name="lock_1" type="fixed">
      <parent>panel_01</parent>
      <child>panel_02</child>
    </joint>

    <joint name="lock_2" type="fixed">
      <parent>panel_small_01</parent>
      <child>panel_small_03</child>
    </joint>

    <joint name="lock_3" type="fixed">
      <parent>panel_small_02</parent>
      <child>panel_small_04</child>
    </joint>

    <plugin name="solar_panel_plugin" filename="libSolarPanelPlugin.so">
    </plugin>

  </model>

</sdf>
